<sdf version='1.11'>
  <model name='h1_2'>
    <link name='pelvis'>
      <inertial>
        <pose>-0.00040000000000000002 3.6999999999999998e-05 -0.046864000000000003 0 0 0</pose>
        <mass>5.9829999999999997</mass>
        <inertia>
          <ixx>0.049168411000000002</ixx>
          <ixy>-1.9868999999999999e-05</ixy>
          <ixz>-4.846e-05</ixz>
          <iyy>0.0090258439999999999</iyy>
          <iyz>3.4309999999999998e-06</iyz>
          <izz>0.053155890999999997</izz>
        </inertia>
      </inertial>
      <collision name='pelvis_collision'>
        <pose>0 0 0 0 0 0</pose>
        <geometry>
          <sphere>
            <radius>0.050000000000000003</radius>
          </sphere>
        </geometry>
      </collision>
      <visual name='pelvis_visual'>
        <pose>0 0 0 0 0 0</pose>
        <geometry>
          <mesh>
            <scale>1 1 1</scale>
            <uri>meshes/pelvis.STL</uri>
          </mesh>
        </geometry>
        <material>
          <diffuse>0.125 0.125 0.125 1</diffuse>
          <ambient>0.125 0.125 0.125 1</ambient>
        </material>
      </visual>
    </link>
    <joint name='left_hip_yaw_joint' type='revolute'>
      <pose relative_to='pelvis'>0 0.087499999999999994 -0.16320000000000001 0 0 0</pose>
      <parent>pelvis</parent>
      <child>left_hip_yaw_link</child>
      <axis>
        <xyz>0 0 1</xyz>
        <limit>
          <lower>-0.42999999999999999</lower>
          <upper>0.42999999999999999</upper>
          <effort>200</effort>
          <velocity>23</velocity>
        </limit>
        <dynamics>
          <spring_reference>0</spring_reference>
          <spring_stiffness>0</spring_stiffness>
        </dynamics>
      </axis>
    </joint>
    <link name='left_hip_yaw_link'>
      <pose relative_to='left_hip_yaw_joint'>0 0 0 0 0 0</pose>
      <inertial>
        <pose>0 -0.026197000000000002 0.0066470000000000001 0 0 0</pose>
        <mass>2.8290000000000002</mass>
        <inertia>
          <ixx>0.0045536049999999996</ixx>
          <ixy>5.0000000000000001e-09</ixy>
          <ixz>8.1699999999999997e-07</ixz>
          <iyy>0.0056887300000000003</iyy>
          <iyz>-0.00034515700000000002</iyz>
          <izz>0.003548907</izz>
        </inertia>
      </inertial>
      <collision name='left_hip_yaw_link_collision'>
        <pose>0.02 0 0 0 1.5707963267948966 0</pose>
        <geometry>
          <cylinder>
            <length>0.02</length>
            <radius>0.01</radius>
          </cylinder>
        </geometry>
      </collision>
      <visual name='left_hip_yaw_link_visual'>
        <pose>0 0 0 0 0 0</pose>
        <geometry>
          <mesh>
            <scale>1 1 1</scale>
            <uri>meshes/left_hip_yaw_link.STL</uri>
          </mesh>
        </geometry>
        <material>
          <diffuse>0.125 0.125 0.125 1</diffuse>
          <ambient>0.125 0.125 0.125 1</ambient>
        </material>
      </visual>
    </link>
    <joint name='left_hip_pitch_joint' type='revolute'>
      <pose relative_to='left_hip_yaw_link'>0 0.075499999999999998 0 0 0 0</pose>
      <parent>left_hip_yaw_link</parent>
      <child>left_hip_pitch_link</child>
      <axis>
        <xyz>0 1 0</xyz>
        <limit>
          <lower>-3.1400000000000001</lower>
          <upper>2.5</upper>
          <effort>200</effort>
          <velocity>23</velocity>
        </limit>
        <dynamics>
          <spring_reference>0</spring_reference>
          <spring_stiffness>0</spring_stiffness>
        </dynamics>
      </axis>
    </joint>
    <link name='left_hip_pitch_link'>
      <pose relative_to='left_hip_pitch_joint'>0 0 0 0 0 0</pose>
      <inertial>
        <pose>-0.0078100000000000001 -0.0047239999999999999 -6.3e-05 0 0 0</pose>
        <mass>2.9199999999999999</mass>
        <inertia>
          <ixx>0.0055947000000000002</ixx>
          <ixy>0.000143308</ixy>
          <ixz>-1.1847e-05</ixz>
          <iyy>0.0038625809999999999</iyy>
          <iyz>-9.6069999999999997e-06</iyz>
          <izz>0.0044505630000000003</izz>
        </inertia>
      </inertial>
      <collision name='left_hip_pitch_link_collision'>
        <pose>0 0 -0.20000000000000001 0 0 0</pose>
        <geometry>
          <cylinder>
            <length>0.20000000000000001</length>
            <radius>0.02</radius>
          </cylinder>
        </geometry>
      </collision>
      <visual name='left_hip_pitch_link_visual'>
        <pose>0 0 0 0 0 0</pose>
        <geometry>
          <mesh>
            <scale>1 1 1</scale>
            <uri>meshes/left_hip_pitch_link.STL</uri>
          </mesh>
        </geometry>
        <material>
          <diffuse>0.125 0.125 0.125 1</diffuse>
          <ambient>0.125 0.125 0.125 1</ambient>
        </material>
      </visual>
    </link>
    <joint name='left_hip_roll_joint' type='revolute'>
      <pose relative_to='left_hip_pitch_link'>0 0 0 0 0 0</pose>
      <parent>left_hip_pitch_link</parent>
      <child>left_hip_roll_link</child>
      <axis>
        <xyz>1 0 0</xyz>
        <limit>
          <lower>-0.42999999999999999</lower>
          <upper>3.1400000000000001</upper>
          <effort>200</effort>
          <velocity>23</velocity>
        </limit>
        <dynamics>
          <spring_reference>0</spring_reference>
          <spring_stiffness>0</spring_stiffness>
        </dynamics>
      </axis>
    </joint>
    <link name='left_hip_roll_link'>
      <pose relative_to='left_hip_roll_joint'>0 0 0 0 0 0</pose>
      <inertial>
        <pose>0.0041710000000000002 -0.0085760000000000003 -0.19450899999999999 0 0 0</pose>
        <mass>4.9619999999999997</mass>
        <inertia>
          <ixx>0.046305869</ixx>
          <ixy>-0.00032262600000000001</ixy>
          <ixz>-0.0011997030000000001</ixz>
          <iyy>0.047955402000000001</iyy>
          <iyz>0.00028814699999999999</iyz>
          <izz>0.0089145179999999997</izz>
        </inertia>
      </inertial>
      <collision name='left_hip_roll_link_collision'>
        <pose>0 0.059999999999999998 0 1.5707963267948959 0 0</pose>
        <geometry>
          <cylinder>
            <length>0.01</length>
            <radius>0.02</radius>
          </cylinder>
        </geometry>
      </collision>
      <visual name='left_hip_roll_link_visual'>
        <pose>0 0 0 0 0 0</pose>
        <geometry>
          <mesh>
            <scale>1 1 1</scale>
            <uri>meshes/left_hip_roll_link.STL</uri>
          </mesh>
        </geometry>
        <material>
          <diffuse>0.125 0.125 0.125 1</diffuse>
          <ambient>0.125 0.125 0.125 1</ambient>
        </material>
      </visual>
    </link>
    <joint name='left_knee_joint' type='revolute'>
      <pose relative_to='left_hip_roll_link'>0 0 -0.40000000000000002 0 0 0</pose>
      <parent>left_hip_roll_link</parent>
      <child>left_knee_link</child>
      <axis>
        <xyz>0 1 0</xyz>
        <limit>
          <lower>-0.12</lower>
          <upper>2.1899999999999999</upper>
          <effort>300</effort>
          <velocity>14</velocity>
        </limit>
        <dynamics>
          <spring_reference>0</spring_reference>
          <spring_stiffness>0</spring_stiffness>
        </dynamics>
      </axis>
    </joint>
    <link name='left_knee_link'>
      <pose relative_to='left_knee_joint'>0 0 0 0 0 0</pose>
      <inertial>
        <pose>0.00017899999999999999 0.000121 -0.168936 0 0 0</pose>
        <mass>3.839</mass>
        <inertia>
          <ixx>0.039002362999999998</ixx>
          <ixy>-7.2364e-05</ixy>
          <ixz>-0.00079450600000000005</ixz>
          <iyy>0.039042375999999997</iyy>
          <iyz>-1.8663000000000001e-05</iyz>
          <izz>0.0050298290000000004</izz>
        </inertia>
      </inertial>
      <collision name='left_knee_link_collision'>
        <pose>0 0 -0.20000000000000001 0 0 0</pose>
        <geometry>
          <cylinder>
            <length>0.20000000000000001</length>
            <radius>0.02</radius>
          </cylinder>
        </geometry>
      </collision>
      <visual name='left_knee_link_visual'>
        <pose>0 0 0 0 0 0</pose>
        <geometry>
          <mesh>
            <scale>1 1 1</scale>
            <uri>meshes/left_knee_link.STL</uri>
          </mesh>
        </geometry>
        <material>
          <diffuse>0.125 0.125 0.125 1</diffuse>
          <ambient>0.125 0.125 0.125 1</ambient>
        </material>
      </visual>
    </link>
    <joint name='left_ankle_pitch_joint' type='revolute'>
      <pose relative_to='left_knee_link'>0 0 -0.40000000000000002 0 0 0</pose>
      <parent>left_knee_link</parent>
      <child>left_ankle_pitch_link</child>
      <axis>
        <xyz>0 1 0</xyz>
        <limit>
          <lower>-0.89733399999999996</lower>
          <upper>0.52359800000000001</upper>
          <effort>60</effort>
          <velocity>9</velocity>
        </limit>
        <dynamics>
          <spring_reference>0</spring_reference>
          <spring_stiffness>0</spring_stiffness>
        </dynamics>
      </axis>
    </joint>
    <link name='left_ankle_pitch_link'>
      <pose relative_to='left_ankle_pitch_joint'>0 0 0 0 0 0</pose>
      <inertial>
        <pose>-0.00029399999999999999 0 -0.010794 0 0 0</pose>
        <mass>0.10199999999999999</mass>
        <inertia>
          <ixx>2.3944e-05</ixx>
          <ixy>0</ixy>
          <ixz>1.2100000000000001e-07</ixz>
          <iyy>2.1837000000000001e-05</iyy>
          <iyz>0</iyz>
          <izz>1.3414000000000001e-05</izz>
        </inertia>
      </inertial>
      <collision name='left_ankle_pitch_link_collision'>
        <pose>0 0 0 0 0 0</pose>
        <geometry>
          <mesh>
            <scale>1 1 1</scale>
            <uri>meshes/left_ankle_pitch_link.STL</uri>
          </mesh>
        </geometry>
      </collision>
      <visual name='left_ankle_pitch_link_visual'>
        <pose>0 0 0 0 0 0</pose>
        <geometry>
          <mesh>
            <scale>1 1 1</scale>
            <uri>meshes/left_ankle_pitch_link.STL</uri>
          </mesh>
        </geometry>
        <material>
          <diffuse>0.125 0.125 0.125 1</diffuse>
          <ambient>0.125 0.125 0.125 1</ambient>
        </material>
      </visual>
    </link>
    <joint name='left_ankle_roll_joint' type='revolute'>
      <pose relative_to='left_ankle_pitch_link'>0 0 -0.02 0 0 0</pose>
      <parent>left_ankle_pitch_link</parent>
      <child>left_ankle_roll_link</child>
      <axis>
        <xyz>1 0 0</xyz>
        <limit>
          <lower>-0.261799</lower>
          <upper>0.261799</upper>
          <effort>40</effort>
          <velocity>9</velocity>
        </limit>
        <dynamics>
          <spring_reference>0</spring_reference>
          <spring_stiffness>0</spring_stiffness>
        </dynamics>
      </axis>
    </joint>
    <link name='left_ankle_roll_link'>
      <pose relative_to='left_ankle_roll_joint'>0 0 0 0 0 0</pose>
      <inertial>
        <pose>0.029589000000000001 0 -0.015973000000000001 0 0 0</pose>
        <mass>0.747</mass>
        <inertia>
          <ixx>0.00064882999999999998</ixx>
          <ixy>0</ixy>
          <ixz>0.00015838000000000001</ixz>
          <iyy>0.0034353389999999999</iyy>
          <iyz>0</iyz>
          <izz>0.0035832590000000001</izz>
        </inertia>
      </inertial>
      <collision name='left_ankle_roll_link_collision'>
        <pose>0 0 0 0 0 0</pose>
        <geometry>
          <mesh>
            <scale>1 1 1</scale>
            <uri>meshes/left_ankle_roll_link.STL</uri>
          </mesh>
        </geometry>
      </collision>
      <visual name='left_ankle_roll_link_visual'>
        <pose>0 0 0 0 0 0</pose>
        <geometry>
          <mesh>
            <scale>1 1 1</scale>
            <uri>meshes/left_ankle_roll_link.STL</uri>
          </mesh>
        </geometry>
        <material>
          <diffuse>0.125 0.125 0.125 1</diffuse>
          <ambient>0.125 0.125 0.125 1</ambient>
        </material>
      </visual>
    </link>
    <joint name='right_hip_yaw_joint' type='revolute'>
      <pose relative_to='pelvis'>0 -0.087499999999999994 -0.16320000000000001 0 0 0</pose>
      <parent>pelvis</parent>
      <child>right_hip_yaw_link</child>
      <axis>
        <xyz>0 0 1</xyz>
        <limit>
          <lower>-0.42999999999999999</lower>
          <upper>0.42999999999999999</upper>
          <effort>200</effort>
          <velocity>23</velocity>
        </limit>
        <dynamics>
          <spring_reference>0</spring_reference>
          <spring_stiffness>0</spring_stiffness>
        </dynamics>
      </axis>
    </joint>
    <link name='right_hip_yaw_link'>
      <pose relative_to='right_hip_yaw_joint'>0 0 0 0 0 0</pose>
      <inertial>
        <pose>0 0.026197000000000002 0.0066470000000000001 0 0 0</pose>
        <mass>2.8290000000000002</mass>
        <inertia>
          <ixx>0.0045536049999999996</ixx>
          <ixy>-5.0000000000000001e-09</ixy>
          <ixz>8.1699999999999997e-07</ixz>
          <iyy>0.0056887300000000003</iyy>
          <iyz>0.00034515700000000002</iyz>
          <izz>0.003548907</izz>
        </inertia>
      </inertial>
      <collision name='right_hip_yaw_link_collision'>
        <pose>0.02 0 0 0 1.5707963267948966 0</pose>
        <geometry>
          <cylinder>
            <length>0.02</length>
            <radius>0.01</radius>
          </cylinder>
        </geometry>
      </collision>
      <visual name='right_hip_yaw_link_visual'>
        <pose>0 0 0 0 0 0</pose>
        <geometry>
          <mesh>
            <scale>1 1 1</scale>
            <uri>meshes/right_hip_yaw_link.STL</uri>
          </mesh>
        </geometry>
        <material>
          <diffuse>0.125 0.125 0.125 1</diffuse>
          <ambient>0.125 0.125 0.125 1</ambient>
        </material>
      </visual>
    </link>
    <joint name='right_hip_pitch_joint' type='revolute'>
      <pose relative_to='right_hip_yaw_link'>0 -0.075499999999999998 0 0 0 0</pose>
      <parent>right_hip_yaw_link</parent>
      <child>right_hip_pitch_link</child>
      <axis>
        <xyz>0 1 0</xyz>
        <limit>
          <lower>-3.1400000000000001</lower>
          <upper>2.5</upper>
          <effort>200</effort>
          <velocity>23</velocity>
        </limit>
        <dynamics>
          <spring_reference>0</spring_reference>
          <spring_stiffness>0</spring_stiffness>
        </dynamics>
      </axis>
    </joint>
    <link name='right_hip_pitch_link'>
      <pose relative_to='right_hip_pitch_joint'>0 0 0 0 0 0</pose>
      <inertial>
        <pose>-0.0078100000000000001 0.0047239999999999999 -6.3e-05 0 0 0</pose>
        <mass>2.9199999999999999</mass>
        <inertia>
          <ixx>0.0055947000000000002</ixx>
          <ixy>-0.000143308</ixy>
          <ixz>-1.1847e-05</ixz>
          <iyy>0.0038625809999999999</iyy>
          <iyz>9.6069999999999997e-06</iyz>
          <izz>0.0044505630000000003</izz>
        </inertia>
      </inertial>
      <collision name='right_hip_pitch_link_collision'>
        <pose>0 0 -0.20000000000000001 0 0 0</pose>
        <geometry>
          <cylinder>
            <length>0.20000000000000001</length>
            <radius>0.02</radius>
          </cylinder>
        </geometry>
      </collision>
      <visual name='right_hip_pitch_link_visual'>
        <pose>0 0 0 0 0 0</pose>
        <geometry>
          <mesh>
            <scale>1 1 1</scale>
            <uri>meshes/right_hip_pitch_link.STL</uri>
          </mesh>
        </geometry>
        <material>
          <diffuse>0.125 0.125 0.125 1</diffuse>
          <ambient>0.125 0.125 0.125 1</ambient>
        </material>
      </visual>
    </link>
    <joint name='right_hip_roll_joint' type='revolute'>
      <pose relative_to='right_hip_pitch_link'>0 0 0 0 0 0</pose>
      <parent>right_hip_pitch_link</parent>
      <child>right_hip_roll_link</child>
      <axis>
        <xyz>1 0 0</xyz>
        <limit>
          <lower>-3.1400000000000001</lower>
          <upper>0.42999999999999999</upper>
          <effort>200</effort>
          <velocity>23</velocity>
        </limit>
        <dynamics>
          <spring_reference>0</spring_reference>
          <spring_stiffness>0</spring_stiffness>
        </dynamics>
      </axis>
    </joint>
    <link name='right_hip_roll_link'>
      <pose relative_to='right_hip_roll_joint'>0 0 0 0 0 0</pose>
      <inertial>
        <pose>0.0041710000000000002 0.0085760000000000003 -0.19450899999999999 0 0 0</pose>
        <mass>4.9619999999999997</mass>
        <inertia>
          <ixx>0.046305869</ixx>
          <ixy>0.00032262600000000001</ixy>
          <ixz>-0.0011997030000000001</ixz>
          <iyy>0.047955402000000001</iyy>
          <iyz>-0.00028814699999999999</iyz>
          <izz>0.0089145179999999997</izz>
        </inertia>
      </inertial>
      <collision name='right_hip_roll_link_collision'>
        <pose>0 -0.059999999999999998 0 1.5707963267948959 0 0</pose>
        <geometry>
          <cylinder>
            <length>0.01</length>
            <radius>0.02</radius>
          </cylinder>
        </geometry>
      </collision>
      <visual name='right_hip_roll_link_visual'>
        <pose>0 0 0 0 0 0</pose>
        <geometry>
          <mesh>
            <scale>1 1 1</scale>
            <uri>meshes/right_hip_roll_link.STL</uri>
          </mesh>
        </geometry>
        <material>
          <diffuse>0.125 0.125 0.125 1</diffuse>
          <ambient>0.125 0.125 0.125 1</ambient>
        </material>
      </visual>
    </link>
    <joint name='right_knee_joint' type='revolute'>
      <pose relative_to='right_hip_roll_link'>0 0 -0.40000000000000002 0 0 0</pose>
      <parent>right_hip_roll_link</parent>
      <child>right_knee_link</child>
      <axis>
        <xyz>0 1 0</xyz>
        <limit>
          <lower>-0.12</lower>
          <upper>2.1899999999999999</upper>
          <effort>300</effort>
          <velocity>14</velocity>
        </limit>
        <dynamics>
          <spring_reference>0</spring_reference>
          <spring_stiffness>0</spring_stiffness>
        </dynamics>
      </axis>
    </joint>
    <link name='right_knee_link'>
      <pose relative_to='right_knee_joint'>0 0 0 0 0 0</pose>
      <inertial>
        <pose>0.00017899999999999999 -0.000121 -0.168936 0 0 0</pose>
        <mass>3.839</mass>
        <inertia>
          <ixx>0.039002362999999998</ixx>
          <ixy>7.2364e-05</ixy>
          <ixz>-0.00079450600000000005</ixz>
          <iyy>0.039042375999999997</iyy>
          <iyz>1.8663000000000001e-05</iyz>
          <izz>0.0050298290000000004</izz>
        </inertia>
      </inertial>
      <collision name='right_knee_link_collision'>
        <pose>0 0 -0.20000000000000001 0 0 0</pose>
        <geometry>
          <cylinder>
            <length>0.20000000000000001</length>
            <radius>0.02</radius>
          </cylinder>
        </geometry>
      </collision>
      <visual name='right_knee_link_visual'>
        <pose>0 0 0 0 0 0</pose>
        <geometry>
          <mesh>
            <scale>1 1 1</scale>
            <uri>meshes/right_knee_link.STL</uri>
          </mesh>
        </geometry>
        <material>
          <diffuse>0.125 0.125 0.125 1</diffuse>
          <ambient>0.125 0.125 0.125 1</ambient>
        </material>
      </visual>
    </link>
    <joint name='right_ankle_pitch_joint' type='revolute'>
      <pose relative_to='right_knee_link'>0 0 -0.40000000000000002 0 0 0</pose>
      <parent>right_knee_link</parent>
      <child>right_ankle_pitch_link</child>
      <axis>
        <xyz>0 1 0</xyz>
        <limit>
          <lower>-0.89733399999999996</lower>
          <upper>0.52359800000000001</upper>
          <effort>60</effort>
          <velocity>9</velocity>
        </limit>
        <dynamics>
          <spring_reference>0</spring_reference>
          <spring_stiffness>0</spring_stiffness>
        </dynamics>
      </axis>
    </joint>
    <link name='right_ankle_pitch_link'>
      <pose relative_to='right_ankle_pitch_joint'>0 0 0 0 0 0</pose>
      <inertial>
        <pose>-0.00029399999999999999 0 -0.010794 0 0 0</pose>
        <mass>0.10199999999999999</mass>
        <inertia>
          <ixx>2.3944e-05</ixx>
          <ixy>0</ixy>
          <ixz>1.2100000000000001e-07</ixz>
          <iyy>2.1837000000000001e-05</iyy>
          <iyz>0</iyz>
          <izz>1.3414000000000001e-05</izz>
        </inertia>
      </inertial>
      <collision name='right_ankle_pitch_link_collision'>
        <pose>0 0 0 0 0 0</pose>
        <geometry>
          <mesh>
            <scale>1 1 1</scale>
            <uri>meshes/right_ankle_pitch_link.STL</uri>
          </mesh>
        </geometry>
      </collision>
      <visual name='right_ankle_pitch_link_visual'>
        <pose>0 0 0 0 0 0</pose>
        <geometry>
          <mesh>
            <scale>1 1 1</scale>
            <uri>meshes/right_ankle_pitch_link.STL</uri>
          </mesh>
        </geometry>
        <material>
          <diffuse>0.125 0.125 0.125 1</diffuse>
          <ambient>0.125 0.125 0.125 1</ambient>
        </material>
      </visual>
    </link>
    <joint name='right_ankle_roll_joint' type='revolute'>
      <pose relative_to='right_ankle_pitch_link'>0 0 -0.02 0 0 0</pose>
      <parent>right_ankle_pitch_link</parent>
      <child>right_ankle_roll_link</child>
      <axis>
        <xyz>1 0 0</xyz>
        <limit>
          <lower>-0.261799</lower>
          <upper>0.261799</upper>
          <effort>40</effort>
          <velocity>9</velocity>
        </limit>
        <dynamics>
          <spring_reference>0</spring_reference>
          <spring_stiffness>0</spring_stiffness>
        </dynamics>
      </axis>
    </joint>
    <link name='right_ankle_roll_link'>
      <pose relative_to='right_ankle_roll_joint'>0 0 0 0 0 0</pose>
      <inertial>
        <pose>0.029589000000000001 0 -0.015973000000000001 0 0 0</pose>
        <mass>0.747</mass>
        <inertia>
          <ixx>0.00064882999999999998</ixx>
          <ixy>0</ixy>
          <ixz>0.00015838000000000001</ixz>
          <iyy>0.0034353389999999999</iyy>
          <iyz>0</iyz>
          <izz>0.0035832590000000001</izz>
        </inertia>
      </inertial>
      <collision name='right_ankle_roll_link_collision'>
        <pose>0 0 0 0 0 0</pose>
        <geometry>
          <mesh>
            <scale>1 1 1</scale>
            <uri>meshes/right_ankle_roll_link.STL</uri>
          </mesh>
        </geometry>
      </collision>
      <visual name='right_ankle_roll_link_visual'>
        <pose>0 0 0 0 0 0</pose>
        <geometry>
          <mesh>
            <scale>1 1 1</scale>
            <uri>meshes/right_ankle_roll_link.STL</uri>
          </mesh>
        </geometry>
        <material>
          <diffuse>0.125 0.125 0.125 1</diffuse>
          <ambient>0.125 0.125 0.125 1</ambient>
        </material>
      </visual>
    </link>
    <joint name='torso_joint' type='revolute'>
      <pose relative_to='pelvis'>0 0 0 0 0 0</pose>
      <parent>pelvis</parent>
      <child>torso_link</child>
      <axis>
        <xyz>0 0 1</xyz>
        <limit>
          <lower>-2.3500000000000001</lower>
          <upper>2.3500000000000001</upper>
          <effort>200</effort>
          <velocity>23</velocity>
        </limit>
        <dynamics>
          <spring_reference>0</spring_reference>
          <spring_stiffness>0</spring_stiffness>
        </dynamics>
      </axis>
    </joint>
    <link name='torso_link'>
      <pose relative_to='torso_joint'>0 0 0 0 0 0</pose>
      <inertial>
        <pose>0.00048899999999999996 0.002797 0.20483999999999999 0 0 0</pose>
        <mass>17.789000000000001</mass>
        <inertia>
          <ixx>0.48730000000000001</ixx>
          <ixy>-0.00053762999999999999</ixy>
          <ixz>0.0020276000000000001</ixz>
          <iyy>0.40962999999999999</iyy>
          <iyz>-0.00074582000000000001</iyz>
          <izz>0.12784999999999999</izz>
        </inertia>
      </inertial>
      <collision name='torso_link_collision'>
        <pose>0 0 0.14999999999999999 0 0 0</pose>
        <geometry>
          <box>
            <size>0.080000000000000002 0.16 0.10000000000000001</size>
          </box>
        </geometry>
      </collision>
      <visual name='torso_link_visual'>
        <pose>0 0 0 0 0 0</pose>
        <geometry>
          <mesh>
            <scale>1 1 1</scale>
            <uri>meshes/torso_link.STL</uri>
          </mesh>
        </geometry>
        <material>
          <diffuse>0.125 0.125 0.125 1</diffuse>
          <ambient>0.125 0.125 0.125 1</ambient>
        </material>
      </visual>
      <visual name='torso_link_fixed_joint_lump__logo_link_visual_1'>
        <pose>0 0 0 0 0 0</pose>
        <geometry>
          <mesh>
            <scale>1 1 1</scale>
            <uri>meshes/logo_link.STL</uri>
          </mesh>
        </geometry>
        <material>
          <diffuse>1 1 1 1</diffuse>
          <ambient>1 1 1 1</ambient>
        </material>
      </visual>
    </link>
    <joint name='left_shoulder_pitch_joint' type='revolute'>
      <pose relative_to='torso_link'>0 0.14806 0.42332999999999998 0.26180000000000003 0 0</pose>
      <parent>torso_link</parent>
      <child>left_shoulder_pitch_link</child>
      <axis>
        <xyz>0 1 0</xyz>
        <limit>
          <lower>-3.1400000000000001</lower>
          <upper>1.5700000000000001</upper>
          <effort>40</effort>
          <velocity>9</velocity>
        </limit>
        <dynamics>
          <spring_reference>0</spring_reference>
          <spring_stiffness>0</spring_stiffness>
        </dynamics>
      </axis>
    </joint>
    <link name='left_shoulder_pitch_link'>
      <pose relative_to='left_shoulder_pitch_joint'>0 0 0 0 0 0</pose>
      <inertial>
        <pose>0.0030530000000000002 0.060420000000000001 -0.0058999999999999999 0 0 0</pose>
        <mass>1.327</mass>
        <inertia>
          <ixx>0.00058661</ixx>
          <ixy>-2.0157e-05</ixy>
          <ixz>2.9849999999999998e-06</ixz>
          <iyy>0.00039889999999999999</iyy>
          <iyz>2.2379999999999999e-05</iyz>
          <izz>0.00052935999999999999</izz>
        </inertia>
      </inertial>
      <collision name='left_shoulder_pitch_link_collision'>
        <pose>0 0 0 0 0 0</pose>
        <geometry>
          <mesh>
            <scale>1 1 1</scale>
            <uri>meshes/left_shoulder_pitch_link.STL</uri>
          </mesh>
        </geometry>
      </collision>
      <visual name='left_shoulder_pitch_link_visual'>
        <pose>0 0 0 0 0 0</pose>
        <geometry>
          <mesh>
            <scale>1 1 1</scale>
            <uri>meshes/left_shoulder_pitch_link.STL</uri>
          </mesh>
        </geometry>
        <material>
          <diffuse>0.125 0.125 0.125 1</diffuse>
          <ambient>0.125 0.125 0.125 1</ambient>
        </material>
      </visual>
    </link>
    <joint name='left_shoulder_roll_joint' type='revolute'>
      <pose relative_to='left_shoulder_pitch_link'>0.034200000000000001 0.061998999999999999 -0.0060010999999999997 -0.26180000000000003 0 0</pose>
      <parent>left_shoulder_pitch_link</parent>
      <child>left_shoulder_roll_link</child>
      <axis>
        <xyz>1 0 0</xyz>
        <limit>
          <lower>-0.38</lower>
          <upper>3.3999999999999999</upper>
          <effort>40</effort>
          <velocity>9</velocity>
        </limit>
        <dynamics>
          <spring_reference>0</spring_reference>
          <spring_stiffness>0</spring_stiffness>
        </dynamics>
      </axis>
    </joint>
    <link name='left_shoulder_roll_link'>
      <pose relative_to='left_shoulder_roll_joint'>0 0 0 0 0 0</pose>
      <inertial>
        <pose>-0.030932000000000001 -9.9999999999999995e-07 -0.10609 0 0 0</pose>
        <mass>1.393</mass>
        <inertia>
          <ixx>0.0018408000000000001</ixx>
          <ixy>3.9799999999999999e-07</ixy>
          <ixz>-0.00048324000000000002</ixz>
          <iyy>0.001934638</iyy>
          <iyz>1.61e-07</iyz>
          <izz>0.00061773299999999998</izz>
        </inertia>
      </inertial>
      <collision name='left_shoulder_roll_link_collision'>
        <pose>0 0 0 0 0 0</pose>
        <geometry>
          <mesh>
            <scale>1 1 1</scale>
            <uri>meshes/left_shoulder_roll_link.STL</uri>
          </mesh>
        </geometry>
      </collision>
      <visual name='left_shoulder_roll_link_visual'>
        <pose>0 0 0 0 0 0</pose>
        <geometry>
          <mesh>
            <scale>1 1 1</scale>
            <uri>meshes/left_shoulder_roll_link.STL</uri>
          </mesh>
        </geometry>
        <material>
          <diffuse>0.125 0.125 0.125 1</diffuse>
          <ambient>0.125 0.125 0.125 1</ambient>
        </material>
      </visual>
    </link>
    <joint name='left_shoulder_yaw_joint' type='revolute'>
      <pose relative_to='left_shoulder_roll_link'>-0.034200000000000001 0 -0.14560000000000001 0 0 0</pose>
      <parent>left_shoulder_roll_link</parent>
      <child>left_shoulder_yaw_link</child>
      <axis>
        <xyz>0 0 1</xyz>
        <limit>
          <lower>-2.6600000000000001</lower>
          <upper>3.0099999999999998</upper>
          <effort>18</effort>
          <velocity>20</velocity>
        </limit>
        <dynamics>
          <spring_reference>0</spring_reference>
          <spring_stiffness>0</spring_stiffness>
        </dynamics>
      </axis>
    </joint>
    <link name='left_shoulder_yaw_link'>
      <pose relative_to='left_shoulder_yaw_joint'>0 0 0 0 0 0</pose>
      <inertial>
        <pose>0.0045830000000000003 0.0011280000000000001 -0.0011280000000000001 0 0 0</pose>
        <mass>1.5049999999999999</mass>
        <inertia>
          <ixx>0.0041989999999999996</ixx>
          <ixy>-1.7785999999999999e-05</ixy>
          <ixz>0.00018372000000000001</ixz>
          <iyy>0.0043138999999999999</iyy>
          <iyz>9.2780000000000003e-05</iyz>
          <izz>0.00065755000000000002</izz>
        </inertia>
      </inertial>
      <collision name='left_shoulder_yaw_link_collision'>
        <pose>0 0 0 0 0 0</pose>
        <geometry>
          <mesh>
            <scale>1 1 1</scale>
            <uri>meshes/left_shoulder_yaw_link.STL</uri>
          </mesh>
        </geometry>
      </collision>
      <visual name='left_shoulder_yaw_link_visual'>
        <pose>0 0 0 0 0 0</pose>
        <geometry>
          <mesh>
            <scale>1 1 1</scale>
            <uri>meshes/left_shoulder_yaw_link.STL</uri>
          </mesh>
        </geometry>
        <material>
          <diffuse>0.125 0.125 0.125 1</diffuse>
          <ambient>0.125 0.125 0.125 1</ambient>
        </material>
      </visual>
    </link>
    <joint name='left_elbow_joint' type='revolute'>
      <pose relative_to='left_shoulder_yaw_link'>0.0060000000000000001 0.032899999999999999 -0.182 0 0 0</pose>
      <parent>left_shoulder_yaw_link</parent>
      <child>left_elbow_link</child>
      <axis>
        <xyz>0 1 0</xyz>
        <limit>
          <lower>-0.94999999999999996</lower>
          <upper>3.1800000000000002</upper>
          <effort>18</effort>
          <velocity>20</velocity>
        </limit>
        <dynamics>
          <spring_reference>0</spring_reference>
          <spring_stiffness>0</spring_stiffness>
        </dynamics>
      </axis>
    </joint>
    <link name='left_elbow_link'>
      <pose relative_to='left_elbow_joint'>0 0 0 0 0 0</pose>
      <inertial>
        <pose>0.077091999999999994 -0.028750999999999999 -0.0097140000000000004 0 0 0</pose>
        <mass>0.69099999999999995</mass>
        <inertia>
          <ixx>0.00031849100000000001</ixx>
          <ixy>0.00022455399999999999</ixy>
          <ixz>6.6207599999999999e-05</ixz>
          <iyy>0.00086122399999999995</iyy>
          <iyz>-2.3329e-05</iyz>
          <izz>0.00089789899999999996</izz>
        </inertia>
      </inertial>
      <collision name='left_elbow_link_collision'>
        <pose>0 0 0 0 0 0</pose>
        <geometry>
          <mesh>
            <scale>1 1 1</scale>
            <uri>meshes/left_elbow_link.STL</uri>
          </mesh>
        </geometry>
      </collision>
      <visual name='left_elbow_link_visual'>
        <pose>0 0 0 0 0 0</pose>
        <geometry>
          <mesh>
            <scale>1 1 1</scale>
            <uri>meshes/left_elbow_link.STL</uri>
          </mesh>
        </geometry>
        <material>
          <diffuse>0.125 0.125 0.125 1</diffuse>
          <ambient>0.125 0.125 0.125 1</ambient>
        </material>
      </visual>
    </link>
    <joint name='left_wrist_roll_joint' type='revolute'>
      <pose relative_to='left_elbow_link'>0.121 -0.032899999999999999 -0.010999999999999999 0 0 0</pose>
      <parent>left_elbow_link</parent>
      <child>left_wrist_roll_link</child>
      <axis>
        <xyz>1 0 0</xyz>
        <limit>
          <lower>-3.0099999999999998</lower>
          <upper>2.75</upper>
          <effort>19</effort>
          <velocity>31.399999999999999</velocity>
        </limit>
        <dynamics>
          <spring_reference>0</spring_reference>
          <spring_stiffness>0</spring_stiffness>
        </dynamics>
      </axis>
    </joint>
    <link name='left_wrist_roll_link'>
      <pose relative_to='left_wrist_roll_joint'>0 0 0 0 0 0</pose>
      <inertial>
        <pose>0.035281 -0.00232 0.00033700000000000001 0 0 0</pose>
        <mass>0.68300000000000005</mass>
        <inertia>
          <ixx>0.00031327500000000001</ixx>
          <ixy>1.6521e-05</ixy>
          <ixz>-2.5009999999999999e-06</ixz>
          <iyy>0.00031041199999999998</iyy>
          <iyz>5.4349999999999996e-06</iyz>
          <izz>0.00034599799999999998</izz>
        </inertia>
      </inertial>
      <collision name='left_wrist_roll_link_collision'>
        <pose>0 0 0 0 0 0</pose>
        <geometry>
          <mesh>
            <scale>1 1 1</scale>
            <uri>meshes/left_wrist_roll_link.STL</uri>
          </mesh>
        </geometry>
      </collision>
      <visual name='left_wrist_roll_link_visual'>
        <pose>0 0 0 0 0 0</pose>
        <geometry>
          <mesh>
            <scale>1 1 1</scale>
            <uri>meshes/left_wrist_roll_link.STL</uri>
          </mesh>
        </geometry>
        <material>
          <diffuse>0.125 0.125 0.125 1</diffuse>
          <ambient>0.125 0.125 0.125 1</ambient>
        </material>
      </visual>
    </link>
    <joint name='left_wrist_pitch_joint' type='revolute'>
      <pose relative_to='left_wrist_roll_link'>0.086999999999999994 0 0 0 0 0</pose>
      <parent>left_wrist_roll_link</parent>
      <child>left_wrist_pitch_link</child>
      <axis>
        <xyz>0 1 0</xyz>
        <limit>
          <lower>-0.46250000000000002</lower>
          <upper>0.46250000000000002</upper>
          <effort>19</effort>
          <velocity>31.399999999999999</velocity>
        </limit>
        <dynamics>
          <spring_reference>0</spring_reference>
          <spring_stiffness>0</spring_stiffness>
        </dynamics>
      </axis>
    </joint>
    <link name='left_wrist_pitch_link'>
      <pose relative_to='left_wrist_pitch_joint'>0 0 0 0 0 0</pose>
      <inertial>
        <pose>0.020395 3.6000000000000001e-05 -0.0029729999999999999 0 0 0</pose>
        <mass>0.48399999999999999</mass>
        <inertia>
          <ixx>7.1364000000000003e-05</ixx>
          <ixy>3.0800000000000001e-07</ixy>
          <ixz>1.485e-06</ixz>
          <iyy>6.9914999999999997e-05</iyy>
          <iyz>-8.7999999999999994e-08</iyz>
          <izz>7.0702000000000002e-05</izz>
        </inertia>
      </inertial>
      <collision name='left_wrist_pitch_link_collision'>
        <pose>0 0 0 0 0 0</pose>
        <geometry>
          <mesh>
            <scale>1 1 1</scale>
            <uri>meshes/left_wrist_pitch_link.STL</uri>
          </mesh>
        </geometry>
      </collision>
      <visual name='left_wrist_pitch_link_visual'>
        <pose>0 0 0 0 0 0</pose>
        <geometry>
          <mesh>
            <scale>1 1 1</scale>
            <uri>meshes/left_wrist_pitch_link.STL</uri>
          </mesh>
        </geometry>
        <material>
          <diffuse>0.125 0.125 0.125 1</diffuse>
          <ambient>0.125 0.125 0.125 1</ambient>
        </material>
      </visual>
    </link>
    <joint name='left_wrist_yaw_joint' type='revolute'>
      <pose relative_to='left_wrist_pitch_link'>0.02 0 0 0 0 0</pose>
      <parent>left_wrist_pitch_link</parent>
      <child>left_wrist_yaw_link</child>
      <axis>
        <xyz>0 0 1</xyz>
        <limit>
          <lower>-1.27</lower>
          <upper>1.27</upper>
          <effort>19</effort>
          <velocity>31.399999999999999</velocity>
        </limit>
        <dynamics>
          <spring_reference>0</spring_reference>
          <spring_stiffness>0</spring_stiffness>
        </dynamics>
      </axis>
    </joint>
    <link name='left_wrist_yaw_link'>
      <pose relative_to='left_wrist_yaw_joint'>0 0 0 0 0 0</pose>
      <inertial>
        <pose>0.077030310100591484 -0.0013144103153373871 -0.00068616980371472708 0 0 0</pose>
        <mass>0.26543</mass>
        <inertia>
          <ixx>0.00022207061196455799</ixx>
          <ixy>1.3733452147697079e-05</ixy>
          <ixz>1.761767480523045e-05</ixz>
          <iyy>0.00085407162547132065</iyy>
          <iyz>-2.2621806343336801e-06</iyz>
          <izz>0.00072270288582072816</izz>
        </inertia>
      </inertial>
      <collision name='left_wrist_yaw_link_fixed_joint_lump__L_hand_base_link_collision'>
        <pose>0.053999999999999999 0 0 0 0 1.5707963267948959</pose>
        <geometry>
          <mesh>
            <scale>1 1 1</scale>
            <uri>meshes/L_hand_base_link.STL</uri>
          </mesh>
        </geometry>
      </collision>
      <visual name='left_wrist_yaw_link_visual'>
        <pose>0 0 0 0 0 0</pose>
        <geometry>
          <mesh>
            <scale>1 1 1</scale>
            <uri>meshes/wrist_yaw_link.STL</uri>
          </mesh>
        </geometry>
        <material>
          <diffuse>0.125 0.125 0.125 1</diffuse>
          <ambient>0.125 0.125 0.125 1</ambient>
        </material>
      </visual>
      <visual name='left_wrist_yaw_link_fixed_joint_lump__L_hand_base_link_visual_1'>
        <pose>0.053999999999999999 0 0 0 0 1.5707963267948959</pose>
        <geometry>
          <mesh>
            <scale>1 1 1</scale>
            <uri>meshes/L_hand_base_link.STL</uri>
          </mesh>
        </geometry>
        <material>
          <diffuse>0.125 0.125 0.125 1</diffuse>
          <ambient>0.125 0.125 0.125 1</ambient>
        </material>
      </visual>
    </link>
    <joint name='L_index_proximal_joint' type='revolute'>
      <pose relative_to='left_wrist_yaw_link'>0.19053 0.0002853299999999726 0.032267999999999998 -0.03490699999999998 -3.4694469519536142e-18 1.570796326794897</pose>
      <parent>left_wrist_yaw_link</parent>
      <child>L_index_proximal</child>
      <axis>
        <xyz>0 0 -1</xyz>
        <limit>
          <lower>0</lower>
          <upper>1.7</upper>
          <effort>1</effort>
          <velocity>0.5</velocity>
        </limit>
        <dynamics>
          <spring_reference>0</spring_reference>
          <spring_stiffness>0</spring_stiffness>
        </dynamics>
      </axis>
    </joint>
    <link name='L_index_proximal'>
      <pose relative_to='L_index_proximal_joint'>0 0 0 0 0 0</pose>
      <inertial>
        <pose>0.0012971 -0.011934 -0.0059997999999999996 0 0 0</pose>
        <mass>0.0042405000000000003</mass>
        <inertia>
          <ixx>6.6214999999999998e-07</ixx>
          <ixy>1.8442000000000001e-08</ixy>
          <ixz>1.3746e-12</ixz>
          <iyy>2.1166999999999999e-07</iyy>
          <iyz>-1.4773000000000001e-11</iyz>
          <izz>6.9401999999999996e-07</izz>
        </inertia>
      </inertial>
      <collision name='L_index_proximal_collision'>
        <pose>0 0 0 0 0 0</pose>
        <geometry>
          <mesh>
            <scale>1 1 1</scale>
            <uri>meshes/link15_L.STL</uri>
          </mesh>
        </geometry>
      </collision>
      <visual name='L_index_proximal_visual'>
        <pose>0 0 0 0 0 0</pose>
        <geometry>
          <mesh>
            <scale>1 1 1</scale>
            <uri>meshes/link15_L.STL</uri>
          </mesh>
        </geometry>
        <material>
          <diffuse>0.125 0.125 0.125 1</diffuse>
          <ambient>0.125 0.125 0.125 1</ambient>
        </material>
      </visual>
    </link>
    <joint name='L_index_intermediate_joint' type='revolute'>
      <pose relative_to='L_index_proximal'>-0.0024229 -0.032041 -0.001 0 0 0</pose>
      <parent>L_index_proximal</parent>
      <child>L_index_intermediate</child>
      <axis>
        <xyz>0 0 -1</xyz>
        <mimic joint='L_index_proximal_joint'>
          <multiplier>1</multiplier>
          <offset>0</offset>
          <reference>0</reference>
        </mimic>
        <limit>
          <lower>0</lower>
          <upper>1.7</upper>
          <effort>1</effort>
          <velocity>0.5</velocity>
        </limit>
        <dynamics>
          <spring_reference>0</spring_reference>
          <spring_stiffness>0</spring_stiffness>
        </dynamics>
      </axis>
    </joint>
    <link name='L_index_intermediate'>
      <pose relative_to='L_index_intermediate_joint'>0 0 0 0 0 0</pose>
      <inertial>
        <pose>0.0021752999999999998 -0.019567000000000001 -0.0050000000000000001 0 0 0</pose>
        <mass>0.0045681999999999997</mass>
        <inertia>
          <ixx>7.6283999999999997e-07</ixx>
          <ixy>-8.0630000000000001e-08</ixy>
          <ixz>3.6797e-13</ixz>
          <iyy>9.4308e-08</iyy>
          <iyz>1.5742999999999999e-13</iyz>
          <izz>7.8176000000000003e-07</izz>
        </inertia>
      </inertial>
      <collision name='L_index_intermediate_collision'>
        <pose>0 0 0 0 0 0</pose>
        <geometry>
          <mesh>
            <scale>1 1 1</scale>
            <uri>meshes/link16_L.STL</uri>
          </mesh>
        </geometry>
      </collision>
      <visual name='L_index_intermediate_visual'>
        <pose>0 0 0 0 0 0</pose>
        <geometry>
          <mesh>
            <scale>1 1 1</scale>
            <uri>meshes/link16_L.STL</uri>
          </mesh>
        </geometry>
        <material>
          <diffuse>0.125 0.125 0.125 1</diffuse>
          <ambient>0.125 0.125 0.125 1</ambient>
        </material>
      </visual>
    </link>
    <joint name='L_middle_proximal_joint' type='revolute'>
      <pose relative_to='left_wrist_yaw_link'>0.19109999999999999 0.0002853299999999726 0.01295 0 0 1.5707963267948959</pose>
      <parent>left_wrist_yaw_link</parent>
      <child>L_middle_proximal</child>
      <axis>
        <xyz>0 0 -1</xyz>
        <limit>
          <lower>0</lower>
          <upper>1.7</upper>
          <effort>1</effort>
          <velocity>0.5</velocity>
        </limit>
        <dynamics>
          <spring_reference>0</spring_reference>
          <spring_stiffness>0</spring_stiffness>
        </dynamics>
      </axis>
    </joint>
    <link name='L_middle_proximal'>
      <pose relative_to='L_middle_proximal_joint'>0 0 0 0 0 0</pose>
      <inertial>
        <pose>0.0012971 -0.011934 -0.0059998999999999999 0 0 0</pose>
        <mass>0.0042405000000000003</mass>
        <inertia>
          <ixx>6.6214999999999998e-07</ixx>
          <ixy>1.8442000000000001e-08</ixy>
          <ixz>1.2299e-12</ixz>
          <iyy>2.1166999999999999e-07</iyy>
          <iyz>-1.4484e-11</iyz>
          <izz>6.9401999999999996e-07</izz>
        </inertia>
      </inertial>
      <collision name='L_middle_proximal_collision'>
        <pose>0 0 0 0 0 0</pose>
        <geometry>
          <mesh>
            <scale>1 1 1</scale>
            <uri>meshes/link17_L.STL</uri>
          </mesh>
        </geometry>
      </collision>
      <visual name='L_middle_proximal_visual'>
        <pose>0 0 0 0 0 0</pose>
        <geometry>
          <mesh>
            <scale>1 1 1</scale>
            <uri>meshes/link17_L.STL</uri>
          </mesh>
        </geometry>
        <material>
          <diffuse>0.125 0.125 0.125 1</diffuse>
          <ambient>0.125 0.125 0.125 1</ambient>
        </material>
      </visual>
    </link>
    <joint name='L_middle_intermediate_joint' type='revolute'>
      <pose relative_to='L_middle_proximal'>-0.0024229 -0.032041 -0.001 0 0 0</pose>
      <parent>L_middle_proximal</parent>
      <child>L_middle_intermediate</child>
      <axis>
        <xyz>0 0 -1</xyz>
        <mimic joint='L_middle_proximal_joint'>
          <multiplier>1</multiplier>
          <offset>0</offset>
          <reference>0</reference>
        </mimic>
        <limit>
          <lower>0</lower>
          <upper>1.7</upper>
          <effort>1</effort>
          <velocity>0.5</velocity>
        </limit>
        <dynamics>
          <spring_reference>0</spring_reference>
          <spring_stiffness>0</spring_stiffness>
        </dynamics>
      </axis>
    </joint>
    <link name='L_middle_intermediate'>
      <pose relative_to='L_middle_intermediate_joint'>0 0 0 0 0 0</pose>
      <inertial>
        <pose>0.001921 -0.020795999999999999 -0.0049998999999999998 0 0 0</pose>
        <mass>0.0050397000000000003</mass>
        <inertia>
          <ixx>9.5822999999999997e-07</ixx>
          <ixy>-1.1424999999999999e-07</ixy>
          <ixz>-2.4185999999999998e-12</ixz>
          <iyy>1.0646e-07</iyy>
          <iyz>3.6974e-12</iyz>
          <izz>9.8384999999999991e-07</izz>
        </inertia>
      </inertial>
      <collision name='L_middle_intermediate_collision'>
        <pose>0 0 0 0 0 0</pose>
        <geometry>
          <mesh>
            <scale>1 1 1</scale>
            <uri>meshes/link18_L.STL</uri>
          </mesh>
        </geometry>
      </collision>
      <visual name='L_middle_intermediate_visual'>
        <pose>0 0 0 0 0 0</pose>
        <geometry>
          <mesh>
            <scale>1 1 1</scale>
            <uri>meshes/link18_L.STL</uri>
          </mesh>
        </geometry>
        <material>
          <diffuse>0.125 0.125 0.125 1</diffuse>
          <ambient>0.125 0.125 0.125 1</ambient>
        </material>
      </visual>
    </link>
    <joint name='L_pinky_proximal_joint' type='revolute'>
      <pose relative_to='left_wrist_yaw_link'>0.18970999999999999 0.0002853299999999726 -0.025488 0.10471999999999999 6.9388939039072284e-18 1.570796326794897</pose>
      <parent>left_wrist_yaw_link</parent>
      <child>L_pinky_proximal</child>
      <axis>
        <xyz>0 0 -1</xyz>
        <limit>
          <lower>0</lower>
          <upper>1.7</upper>
          <effort>1</effort>
          <velocity>0.5</velocity>
        </limit>
        <dynamics>
          <spring_reference>0</spring_reference>
          <spring_stiffness>0</spring_stiffness>
        </dynamics>
      </axis>
    </joint>
    <link name='L_pinky_proximal'>
      <pose relative_to='L_pinky_proximal_joint'>0 0 0 0 0 0</pose>
      <inertial>
        <pose>0.0012971 -0.011934 -0.0059998999999999999 0 0 0</pose>
        <mass>0.0042405000000000003</mass>
        <inertia>
          <ixx>6.6214999999999998e-07</ixx>
          <ixy>1.8442000000000001e-08</ixy>
          <ixz>1.0279000000000001e-12</ixz>
          <iyy>2.1166999999999999e-07</iyy>
          <iyz>-1.4277e-11</iyz>
          <izz>6.9401999999999996e-07</izz>
        </inertia>
      </inertial>
      <collision name='L_pinky_proximal_collision'>
        <pose>0 0 0 0 0 0</pose>
        <geometry>
          <mesh>
            <scale>1 1 1</scale>
            <uri>meshes/link21_L.STL</uri>
          </mesh>
        </geometry>
      </collision>
      <visual name='L_pinky_proximal_visual'>
        <pose>0 0 0 0 0 0</pose>
        <geometry>
          <mesh>
            <scale>1 1 1</scale>
            <uri>meshes/link21_L.STL</uri>
          </mesh>
        </geometry>
        <material>
          <diffuse>0.125 0.125 0.125 1</diffuse>
          <ambient>0.125 0.125 0.125 1</ambient>
        </material>
      </visual>
    </link>
    <joint name='L_pinky_intermediate_joint' type='revolute'>
      <pose relative_to='L_pinky_proximal'>-0.0024229 -0.032041 -0.001 0 0 0</pose>
      <parent>L_pinky_proximal</parent>
      <child>L_pinky_intermediate</child>
      <axis>
        <xyz>0 0 -1</xyz>
        <mimic joint='L_pinky_proximal_joint'>
          <multiplier>1</multiplier>
          <offset>0</offset>
          <reference>0</reference>
        </mimic>
        <limit>
          <lower>0</lower>
          <upper>1.7</upper>
          <effort>1</effort>
          <velocity>0.5</velocity>
        </limit>
        <dynamics>
          <spring_reference>0</spring_reference>
          <spring_stiffness>0</spring_stiffness>
        </dynamics>
      </axis>
    </joint>
    <link name='L_pinky_intermediate'>
      <pose relative_to='L_pinky_intermediate_joint'>0 0 0 0 0 0</pose>
      <inertial>
        <pose>0.0024788000000000002 -0.016208 -0.0050001000000000004 0 0 0</pose>
        <mass>0.0036036000000000002</mass>
        <inertia>
          <ixx>4.3923e-07</ixx>
          <ixy>-4.1355000000000002e-08</ixy>
          <ixz>1.2262999999999999e-12</ixz>
          <iyy>7.0315000000000005e-08</iyy>
          <iyz>3.1310999999999999e-12</iyz>
          <izz>4.4881000000000001e-07</izz>
        </inertia>
      </inertial>
      <collision name='L_pinky_intermediate_collision'>
        <pose>0 0 0 0 0 0</pose>
        <geometry>
          <mesh>
            <scale>1 1 1</scale>
            <uri>meshes/link22_L.STL</uri>
          </mesh>
        </geometry>
      </collision>
      <visual name='L_pinky_intermediate_visual'>
        <pose>0 0 0 0 0 0</pose>
        <geometry>
          <mesh>
            <scale>1 1 1</scale>
            <uri>meshes/link22_L.STL</uri>
          </mesh>
        </geometry>
        <material>
          <diffuse>0.125 0.125 0.125 1</diffuse>
          <ambient>0.125 0.125 0.125 1</ambient>
        </material>
      </visual>
    </link>
    <joint name='L_ring_proximal_joint' type='revolute'>
      <pose relative_to='left_wrist_yaw_link'>0.19091 0.0002853299999999726 -0.0062871999999999997 0.05235999999999999 3.4694469519536142e-18 1.570796326794897</pose>
      <parent>left_wrist_yaw_link</parent>
      <child>L_ring_proximal</child>
      <axis>
        <xyz>0 0 -1</xyz>
        <limit>
          <lower>0</lower>
          <upper>1.7</upper>
          <effort>1</effort>
          <velocity>0.5</velocity>
        </limit>
        <dynamics>
          <spring_reference>0</spring_reference>
          <spring_stiffness>0</spring_stiffness>
        </dynamics>
      </axis>
    </joint>
    <link name='L_ring_proximal'>
      <pose relative_to='L_ring_proximal_joint'>0 0 0 0 0 0</pose>
      <inertial>
        <pose>0.0012971 -0.011934 -0.0059998999999999999 0 0 0</pose>
        <mass>0.0042405000000000003</mass>
        <inertia>
          <ixx>6.6214999999999998e-07</ixx>
          <ixy>1.8442000000000001e-08</ixy>
          <ixz>9.6052000000000003e-13</ixz>
          <iyy>2.1166999999999999e-07</iyy>
          <iyz>-1.4124000000000001e-11</iyz>
          <izz>6.9401999999999996e-07</izz>
        </inertia>
      </inertial>
      <collision name='L_ring_proximal_collision'>
        <pose>0 0 0 0 0 0</pose>
        <geometry>
          <mesh>
            <scale>1 1 1</scale>
            <uri>meshes/link19_L.STL</uri>
          </mesh>
        </geometry>
      </collision>
      <visual name='L_ring_proximal_visual'>
        <pose>0 0 0 0 0 0</pose>
        <geometry>
          <mesh>
            <scale>1 1 1</scale>
            <uri>meshes/link19_L.STL</uri>
          </mesh>
        </geometry>
        <material>
          <diffuse>0.125 0.125 0.125 1</diffuse>
          <ambient>0.125 0.125 0.125 1</ambient>
        </material>
      </visual>
    </link>
    <joint name='L_ring_intermediate_joint' type='revolute'>
      <pose relative_to='L_ring_proximal'>-0.0024229 -0.032041 -0.001 0 0 0</pose>
      <parent>L_ring_proximal</parent>
      <child>L_ring_intermediate</child>
      <axis>
        <xyz>0 0 -1</xyz>
        <mimic joint='L_ring_proximal_joint'>
          <multiplier>1</multiplier>
          <offset>0</offset>
          <reference>0</reference>
        </mimic>
        <limit>
          <lower>0</lower>
          <upper>1.7</upper>
          <effort>1</effort>
          <velocity>0.5</velocity>
        </limit>
        <dynamics>
          <spring_reference>0</spring_reference>
          <spring_stiffness>0</spring_stiffness>
        </dynamics>
      </axis>
    </joint>
    <link name='L_ring_intermediate'>
      <pose relative_to='L_ring_intermediate_joint'>0 0 0 0 0 0</pose>
      <inertial>
        <pose>0.0021752999999999998 -0.019567000000000001 -0.0050000000000000001 0 0 0</pose>
        <mass>0.0045681999999999997</mass>
        <inertia>
          <ixx>7.6285000000000003e-07</ixx>
          <ixy>-8.0631000000000002e-08</ixy>
          <ixz>3.3472000000000001e-14</ixz>
          <iyy>9.4308e-08</iyy>
          <iyz>-4.4773e-13</iyz>
          <izz>7.8176000000000003e-07</izz>
        </inertia>
      </inertial>
      <collision name='L_ring_intermediate_collision'>
        <pose>0 0 0 0 0 0</pose>
        <geometry>
          <mesh>
            <scale>1 1 1</scale>
            <uri>meshes/link20_L.STL</uri>
          </mesh>
        </geometry>
      </collision>
      <visual name='L_ring_intermediate_visual'>
        <pose>0 0 0 0 0 0</pose>
        <geometry>
          <mesh>
            <scale>1 1 1</scale>
            <uri>meshes/link20_L.STL</uri>
          </mesh>
        </geometry>
        <material>
          <diffuse>0.125 0.125 0.125 1</diffuse>
          <ambient>0.125 0.125 0.125 1</ambient>
        </material>
      </visual>
    </link>
    <joint name='L_thumb_proximal_yaw_joint' type='revolute'>
      <pose relative_to='left_wrist_yaw_link'>0.1231 -0.01696000000000002 0.020449999999999999 -1.5707926536359931 -1.5707926535755432 -1.5707963267344471</pose>
      <parent>left_wrist_yaw_link</parent>
      <child>L_thumb_proximal_base</child>
      <axis>
        <xyz>0 0 1</xyz>
        <limit>
          <lower>-0.10000000000000001</lower>
          <upper>1.3</upper>
          <effort>1</effort>
          <velocity>0.5</velocity>
        </limit>
        <dynamics>
          <spring_reference>0</spring_reference>
          <spring_stiffness>0</spring_stiffness>
        </dynamics>
      </axis>
    </joint>
    <link name='L_thumb_proximal_base'>
      <pose relative_to='L_thumb_proximal_yaw_joint'>0 0 0 0 0 0</pose>
      <inertial>
        <pose>0.0048817000000000001 0.00038781999999999998 -0.0072199999999999999 0 0 0</pose>
        <mass>0.0018868999999999999</mass>
        <inertia>
          <ixx>5.5158000000000003e-08</ixx>
          <ixy>-1.1803e-08</ixy>
          <ixz>-4.6742999999999999e-09</ixz>
          <iyy>8.2163999999999994e-08</iyy>
          <iyz>-1.3520999999999999e-09</iyz>
          <izz>6.7433999999999994e-08</izz>
        </inertia>
      </inertial>
      <collision name='L_thumb_proximal_base_collision'>
        <pose>0 0 0 0 0 0</pose>
        <geometry>
          <mesh>
            <scale>1 1 1</scale>
            <uri>meshes/link11_L.STL</uri>
          </mesh>
        </geometry>
      </collision>
      <visual name='L_thumb_proximal_base_visual'>
        <pose>0 0 0 0 0 0</pose>
        <geometry>
          <mesh>
            <scale>1 1 1</scale>
            <uri>meshes/link11_L.STL</uri>
          </mesh>
        </geometry>
        <material>
          <diffuse>0.125 0.125 0.125 1</diffuse>
          <ambient>0.125 0.125 0.125 1</ambient>
        </material>
      </visual>
    </link>
    <joint name='L_thumb_proximal_pitch_joint' type='revolute'>
      <pose relative_to='L_thumb_proximal_base'>0.0099866999999999994 0.0098241999999999999 -0.0088999999999999999 -1.5708000000000002 1.3877787807814457e-17 0.16938999999999999</pose>
      <parent>L_thumb_proximal_base</parent>
      <child>L_thumb_proximal</child>
      <axis>
        <xyz>0 0 -1</xyz>
        <limit>
          <lower>-0.10000000000000001</lower>
          <upper>0.59999999999999998</upper>
          <effort>1</effort>
          <velocity>0.5</velocity>
        </limit>
        <dynamics>
          <spring_reference>0</spring_reference>
          <spring_stiffness>0</spring_stiffness>
        </dynamics>
      </axis>
    </joint>
    <link name='L_thumb_proximal'>
      <pose relative_to='L_thumb_proximal_pitch_joint'>0 0 0 0 0 0</pose>
      <inertial>
        <pose>0.021936000000000001 -0.012789999999999999 -0.0080385999999999999 0 0 0</pose>
        <mass>0.0066100999999999998</mass>
        <inertia>
          <ixx>1.5693e-06</ixx>
          <ixy>7.8339000000000003e-07</ixy>
          <ixz>8.5959000000000003e-10</ixz>
          <iyy>1.7356e-06</iyy>
          <iyz>1.0378000000000001e-09</iyz>
          <izz>2.7870000000000002e-06</izz>
        </inertia>
      </inertial>
      <collision name='L_thumb_proximal_collision'>
        <pose>0 0 0 0 0 0</pose>
        <geometry>
          <mesh>
            <scale>1 1 1</scale>
            <uri>meshes/link12_L.STL</uri>
          </mesh>
        </geometry>
      </collision>
      <visual name='L_thumb_proximal_visual'>
        <pose>0 0 0 0 0 0</pose>
        <geometry>
          <mesh>
            <scale>1 1 1</scale>
            <uri>meshes/link12_L.STL</uri>
          </mesh>
        </geometry>
        <material>
          <diffuse>0.125 0.125 0.125 1</diffuse>
          <ambient>0.125 0.125 0.125 1</ambient>
        </material>
      </visual>
    </link>
    <joint name='L_thumb_intermediate_joint' type='revolute'>
      <pose relative_to='L_thumb_proximal'>0.044069999999999998 -0.034553 -0.00080000000000000004 0 0 0</pose>
      <parent>L_thumb_proximal</parent>
      <child>L_thumb_intermediate</child>
      <axis>
        <xyz>0 0 -1</xyz>
        <mimic joint='L_thumb_proximal_pitch_joint'>
          <multiplier>1.6000000000000001</multiplier>
          <offset>0</offset>
          <reference>0</reference>
        </mimic>
        <limit>
          <lower>0</lower>
          <upper>0.80000000000000004</upper>
          <effort>1</effort>
          <velocity>0.5</velocity>
        </limit>
        <dynamics>
          <spring_reference>0</spring_reference>
          <spring_stiffness>0</spring_stiffness>
        </dynamics>
      </axis>
    </joint>
    <link name='L_thumb_intermediate'>
      <pose relative_to='L_thumb_intermediate_joint'>0 0 0 0 0 0</pose>
      <inertial>
        <pose>0.0095531000000000001 0.0016282 -0.0072002000000000003 0 0 0</pose>
        <mass>0.0037843999999999998</mass>
        <inertia>
          <ixx>3.6981e-07</ixx>
          <ixy>9.8603e-08</ixy>
          <ixz>-2.8173000000000001e-12</ixz>
          <iyy>3.2394999999999999e-07</iyy>
          <iyz>-2.8028000000000001e-12</iyz>
          <izz>4.6531999999999999e-07</izz>
        </inertia>
      </inertial>
      <collision name='L_thumb_intermediate_collision'>
        <pose>0 0 0 0 0 0</pose>
        <geometry>
          <mesh>
            <scale>1 1 1</scale>
            <uri>meshes/link13_L.STL</uri>
          </mesh>
        </geometry>
      </collision>
      <visual name='L_thumb_intermediate_visual'>
        <pose>0 0 0 0 0 0</pose>
        <geometry>
          <mesh>
            <scale>1 1 1</scale>
            <uri>meshes/link13_L.STL</uri>
          </mesh>
        </geometry>
        <material>
          <diffuse>0.125 0.125 0.125 1</diffuse>
          <ambient>0.125 0.125 0.125 1</ambient>
        </material>
      </visual>
    </link>
    <joint name='L_thumb_distal_joint' type='revolute'>
      <pose relative_to='L_thumb_intermediate'>0.020247999999999999 -0.010156 -0.0011999999999999999 0 0 0</pose>
      <parent>L_thumb_intermediate</parent>
      <child>L_thumb_distal</child>
      <axis>
        <xyz>0 0 -1</xyz>
        <mimic joint='L_thumb_proximal_pitch_joint'>
          <multiplier>2.3999999999999999</multiplier>
          <offset>0</offset>
          <reference>0</reference>
        </mimic>
        <limit>
          <lower>0</lower>
          <upper>1.2</upper>
          <effort>1</effort>
          <velocity>0.5</velocity>
        </limit>
        <dynamics>
          <spring_reference>0</spring_reference>
          <spring_stiffness>0</spring_stiffness>
        </dynamics>
      </axis>
    </joint>
    <link name='L_thumb_distal'>
      <pose relative_to='L_thumb_distal_joint'>0 0 0 0 0 0</pose>
      <inertial>
        <pose>0.0092887999999999998 -0.0049529999999999999 -0.0060032999999999996 0 0 0</pose>
        <mass>0.0033440000000000002</mass>
        <inertia>
          <ixx>1.3631999999999999e-07</ixx>
          <ixy>5.6786999999999998e-08</ixy>
          <ixz>-9.1938999999999999e-11</ixz>
          <iyy>1.4051999999999999e-07</iyy>
          <iyz>1.2145e-10</iyz>
          <izz>2.0025999999999999e-07</izz>
        </inertia>
      </inertial>
      <collision name='L_thumb_distal_collision'>
        <pose>0 0 0 0 0 0</pose>
        <geometry>
          <mesh>
            <scale>1 1 1</scale>
            <uri>meshes/link14_L.STL</uri>
          </mesh>
        </geometry>
      </collision>
      <visual name='L_thumb_distal_visual'>
        <pose>0 0 0 0 0 0</pose>
        <geometry>
          <mesh>
            <scale>1 1 1</scale>
            <uri>meshes/link14_L.STL</uri>
          </mesh>
        </geometry>
        <material>
          <diffuse>0.125 0.125 0.125 1</diffuse>
          <ambient>0.125 0.125 0.125 1</ambient>
        </material>
      </visual>
    </link>
    <joint name='right_shoulder_pitch_joint' type='revolute'>
      <pose relative_to='torso_link'>0 -0.14806 0.42332999999999998 -0.26180000000000003 0 0</pose>
      <parent>torso_link</parent>
      <child>right_shoulder_pitch_link</child>
      <axis>
        <xyz>0 1 0</xyz>
        <limit>
          <lower>-3.1400000000000001</lower>
          <upper>1.5700000000000001</upper>
          <effort>40</effort>
          <velocity>9</velocity>
        </limit>
        <dynamics>
          <spring_reference>0</spring_reference>
          <spring_stiffness>0</spring_stiffness>
        </dynamics>
      </axis>
    </joint>
    <link name='right_shoulder_pitch_link'>
      <pose relative_to='right_shoulder_pitch_joint'>0 0 0 0 0 0</pose>
      <inertial>
        <pose>0.0030530000000000002 -0.060420000000000001 -0.0058999999999999999 0 0 0</pose>
        <mass>1.327</mass>
        <inertia>
          <ixx>0.00058661</ixx>
          <ixy>2.0157e-05</ixy>
          <ixz>2.9849999999999998e-06</ixz>
          <iyy>0.00039889999999999999</iyy>
          <iyz>-2.2379999999999999e-05</iyz>
          <izz>0.00052935999999999999</izz>
        </inertia>
      </inertial>
      <collision name='right_shoulder_pitch_link_collision'>
        <pose>0 0 0 0 0 0</pose>
        <geometry>
          <mesh>
            <scale>1 1 1</scale>
            <uri>meshes/right_shoulder_pitch_link.STL</uri>
          </mesh>
        </geometry>
      </collision>
      <visual name='right_shoulder_pitch_link_visual'>
        <pose>0 0 0 0 0 0</pose>
        <geometry>
          <mesh>
            <scale>1 1 1</scale>
            <uri>meshes/right_shoulder_pitch_link.STL</uri>
          </mesh>
        </geometry>
        <material>
          <diffuse>0.125 0.125 0.125 1</diffuse>
          <ambient>0.125 0.125 0.125 1</ambient>
        </material>
      </visual>
    </link>
    <joint name='right_shoulder_roll_joint' type='revolute'>
      <pose relative_to='right_shoulder_pitch_link'>0.034200000000000001 -0.061998999999999999 -0.0060010999999999997 0.26180000000000003 0 0</pose>
      <parent>right_shoulder_pitch_link</parent>
      <child>right_shoulder_roll_link</child>
      <axis>
        <xyz>1 0 0</xyz>
        <limit>
          <lower>-3.3999999999999999</lower>
          <upper>0.38</upper>
          <effort>40</effort>
          <velocity>9</velocity>
        </limit>
        <dynamics>
          <spring_reference>0</spring_reference>
          <spring_stiffness>0</spring_stiffness>
        </dynamics>
      </axis>
    </joint>
    <link name='right_shoulder_roll_link'>
      <pose relative_to='right_shoulder_roll_joint'>0 0 0 0 0 0</pose>
      <inertial>
        <pose>-0.030932000000000001 9.9999999999999995e-07 -0.10609 0 0 0</pose>
        <mass>1.393</mass>
        <inertia>
          <ixx>0.0018408000000000001</ixx>
          <ixy>-3.9799999999999999e-07</ixy>
          <ixz>-0.00048324000000000002</ixz>
          <iyy>0.001934638</iyy>
          <iyz>-1.61e-07</iyz>
          <izz>0.00061773299999999998</izz>
        </inertia>
      </inertial>
      <collision name='right_shoulder_roll_link_collision'>
        <pose>0 0 0 0 0 0</pose>
        <geometry>
          <mesh>
            <scale>1 1 1</scale>
            <uri>meshes/right_shoulder_roll_link.STL</uri>
          </mesh>
        </geometry>
      </collision>
      <visual name='right_shoulder_roll_link_visual'>
        <pose>0 0 0 0 0 0</pose>
        <geometry>
          <mesh>
            <scale>1 1 1</scale>
            <uri>meshes/right_shoulder_roll_link.STL</uri>
          </mesh>
        </geometry>
        <material>
          <diffuse>0.125 0.125 0.125 1</diffuse>
          <ambient>0.125 0.125 0.125 1</ambient>
        </material>
      </visual>
    </link>
    <joint name='right_shoulder_yaw_joint' type='revolute'>
      <pose relative_to='right_shoulder_roll_link'>-0.034200000000000001 0 -0.14560000000000001 0 0 0</pose>
      <parent>right_shoulder_roll_link</parent>
      <child>right_shoulder_yaw_link</child>
      <axis>
        <xyz>0 0 1</xyz>
        <limit>
          <lower>-3.0099999999999998</lower>
          <upper>2.6600000000000001</upper>
          <effort>18</effort>
          <velocity>20</velocity>
        </limit>
        <dynamics>
          <spring_reference>0</spring_reference>
          <spring_stiffness>0</spring_stiffness>
        </dynamics>
      </axis>
    </joint>
    <link name='right_shoulder_yaw_link'>
      <pose relative_to='right_shoulder_yaw_joint'>0 0 0 0 0 0</pose>
      <inertial>
        <pose>0.0045830000000000003 -0.0011280000000000001 -0.0011280000000000001 0 0 0</pose>
        <mass>1.5049999999999999</mass>
        <inertia>
          <ixx>0.0041989999999999996</ixx>
          <ixy>1.7785999999999999e-05</ixy>
          <ixz>0.00018372000000000001</ixz>
          <iyy>0.0043138999999999999</iyy>
          <iyz>-9.2780000000000003e-05</iyz>
          <izz>0.00065755000000000002</izz>
        </inertia>
      </inertial>
      <collision name='right_shoulder_yaw_link_collision'>
        <pose>0 0 0 0 0 0</pose>
        <geometry>
          <mesh>
            <scale>1 1 1</scale>
            <uri>meshes/right_shoulder_yaw_link.STL</uri>
          </mesh>
        </geometry>
      </collision>
      <visual name='right_shoulder_yaw_link_visual'>
        <pose>0 0 0 0 0 0</pose>
        <geometry>
          <mesh>
            <scale>1 1 1</scale>
            <uri>meshes/right_shoulder_yaw_link.STL</uri>
          </mesh>
        </geometry>
        <material>
          <diffuse>0.125 0.125 0.125 1</diffuse>
          <ambient>0.125 0.125 0.125 1</ambient>
        </material>
      </visual>
    </link>
    <joint name='right_elbow_joint' type='revolute'>
      <pose relative_to='right_shoulder_yaw_link'>0.0060000000000000001 -0.032899999999999999 -0.182 0 0 0</pose>
      <parent>right_shoulder_yaw_link</parent>
      <child>right_elbow_link</child>
      <axis>
        <xyz>0 1 0</xyz>
        <limit>
          <lower>-0.94999999999999996</lower>
          <upper>3.1800000000000002</upper>
          <effort>18</effort>
          <velocity>20</velocity>
        </limit>
        <dynamics>
          <spring_reference>0</spring_reference>
          <spring_stiffness>0</spring_stiffness>
        </dynamics>
      </axis>
    </joint>
    <link name='right_elbow_link'>
      <pose relative_to='right_elbow_joint'>0 0 0 0 0 0</pose>
      <inertial>
        <pose>0.077091999999999994 0.028750999999999999 -0.0097140000000000004 0 0 0</pose>
        <mass>0.69099999999999995</mass>
        <inertia>
          <ixx>0.00031849100000000001</ixx>
          <ixy>-0.00022455399999999999</ixy>
          <ixz>6.6207599999999999e-05</ixz>
          <iyy>0.00086122399999999995</iyy>
          <iyz>2.3329e-05</iyz>
          <izz>0.00089789899999999996</izz>
        </inertia>
      </inertial>
      <collision name='right_elbow_link_collision'>
        <pose>0 0 0 0 0 0</pose>
        <geometry>
          <mesh>
            <scale>1 1 1</scale>
            <uri>meshes/right_elbow_link.STL</uri>
          </mesh>
        </geometry>
      </collision>
      <visual name='right_elbow_link_visual'>
        <pose>0 0 0 0 0 0</pose>
        <geometry>
          <mesh>
            <scale>1 1 1</scale>
            <uri>meshes/right_elbow_link.STL</uri>
          </mesh>
        </geometry>
        <material>
          <diffuse>0.125 0.125 0.125 1</diffuse>
          <ambient>0.125 0.125 0.125 1</ambient>
        </material>
      </visual>
    </link>
    <joint name='right_wrist_roll_joint' type='revolute'>
      <pose relative_to='right_elbow_link'>0.121 0.032899999999999999 -0.010999999999999999 0 0 0</pose>
      <parent>right_elbow_link</parent>
      <child>right_wrist_roll_link</child>
      <axis>
        <xyz>1 0 0</xyz>
        <limit>
          <lower>-2.75</lower>
          <upper>3.0099999999999998</upper>
          <effort>19</effort>
          <velocity>31.399999999999999</velocity>
        </limit>
        <dynamics>
          <spring_reference>0</spring_reference>
          <spring_stiffness>0</spring_stiffness>
        </dynamics>
      </axis>
    </joint>
    <link name='right_wrist_roll_link'>
      <pose relative_to='right_wrist_roll_joint'>0 0 0 0 0 0</pose>
      <inertial>
        <pose>0.035281 -0.00232 0.00033700000000000001 0 0 0</pose>
        <mass>0.68300000000000005</mass>
        <inertia>
          <ixx>0.00031327500000000001</ixx>
          <ixy>1.6521e-05</ixy>
          <ixz>-2.5009999999999999e-06</ixz>
          <iyy>0.00031041199999999998</iyy>
          <iyz>5.4349999999999996e-06</iyz>
          <izz>0.00034599799999999998</izz>
        </inertia>
      </inertial>
      <collision name='right_wrist_roll_link_collision'>
        <pose>0 0 0 0 0 0</pose>
        <geometry>
          <mesh>
            <scale>1 1 1</scale>
            <uri>meshes/right_wrist_roll_link.STL</uri>
          </mesh>
        </geometry>
      </collision>
      <visual name='right_wrist_roll_link_visual'>
        <pose>0 0 0 0 0 0</pose>
        <geometry>
          <mesh>
            <scale>1 1 1</scale>
            <uri>meshes/right_wrist_roll_link.STL</uri>
          </mesh>
        </geometry>
        <material>
          <diffuse>0.125 0.125 0.125 1</diffuse>
          <ambient>0.125 0.125 0.125 1</ambient>
        </material>
      </visual>
    </link>
    <joint name='right_wrist_pitch_joint' type='revolute'>
      <pose relative_to='right_wrist_roll_link'>0.086999999999999994 0 0 0 0 0</pose>
      <parent>right_wrist_roll_link</parent>
      <child>right_wrist_pitch_link</child>
      <axis>
        <xyz>0 1 0</xyz>
        <limit>
          <lower>-0.46250000000000002</lower>
          <upper>0.46250000000000002</upper>
          <effort>19</effort>
          <velocity>31.399999999999999</velocity>
        </limit>
        <dynamics>
          <spring_reference>0</spring_reference>
          <spring_stiffness>0</spring_stiffness>
        </dynamics>
      </axis>
    </joint>
    <link name='right_wrist_pitch_link'>
      <pose relative_to='right_wrist_pitch_joint'>0 0 0 0 0 0</pose>
      <inertial>
        <pose>0.020395 3.6000000000000001e-05 -0.0029729999999999999 0 0 0</pose>
        <mass>0.48399999999999999</mass>
        <inertia>
          <ixx>7.1364000000000003e-05</ixx>
          <ixy>3.0800000000000001e-07</ixy>
          <ixz>1.485e-06</ixz>
          <iyy>6.9914999999999997e-05</iyy>
          <iyz>-8.7999999999999994e-08</iyz>
          <izz>7.0702000000000002e-05</izz>
        </inertia>
      </inertial>
      <collision name='right_wrist_pitch_link_collision'>
        <pose>0 0 0 0 0 0</pose>
        <geometry>
          <mesh>
            <scale>1 1 1</scale>
            <uri>meshes/right_wrist_pitch_link.STL</uri>
          </mesh>
        </geometry>
      </collision>
      <visual name='right_wrist_pitch_link_visual'>
        <pose>0 0 0 0 0 0</pose>
        <geometry>
          <mesh>
            <scale>1 1 1</scale>
            <uri>meshes/right_wrist_pitch_link.STL</uri>
          </mesh>
        </geometry>
        <material>
          <diffuse>0.125 0.125 0.125 1</diffuse>
          <ambient>0.125 0.125 0.125 1</ambient>
        </material>
      </visual>
    </link>
    <joint name='right_wrist_yaw_joint' type='revolute'>
      <pose relative_to='right_wrist_pitch_link'>0.02 0 0 0 0 0</pose>
      <parent>right_wrist_pitch_link</parent>
      <child>right_wrist_yaw_link</child>
      <axis>
        <xyz>0 0 1</xyz>
        <limit>
          <lower>-1.27</lower>
          <upper>1.27</upper>
          <effort>19</effort>
          <velocity>31.399999999999999</velocity>
        </limit>
        <dynamics>
          <spring_reference>0</spring_reference>
          <spring_stiffness>0</spring_stiffness>
        </dynamics>
      </axis>
    </joint>
    <link name='right_wrist_yaw_link'>
      <pose relative_to='right_wrist_yaw_joint'>0 0 0 0 0 0</pose>
      <inertial>
        <pose>0.077030310100591484 0.001301302610857863 -0.00069901109143654121 0 0 0</pose>
        <mass>0.26543</mass>
        <inertia>
          <ixx>0.00022206760364683499</ixx>
          <ixy>-1.3612189426566221e-05</ixy>
          <ixz>1.7705995601135101e-05</ixz>
          <iyy>0.00085349018180110774</iyy>
          <iyz>2.263508995486718e-06</iyz>
          <izz>0.00072212632117321803</izz>
        </inertia>
      </inertial>
      <collision name='right_wrist_yaw_link_fixed_joint_lump__R_hand_base_link_collision'>
        <pose>0.053999999999999999 0 0 3.1415926535897931 0 -1.5707963267948959</pose>
        <geometry>
          <mesh>
            <scale>1 1 1</scale>
            <uri>meshes/R_hand_base_link.STL</uri>
          </mesh>
        </geometry>
      </collision>
      <visual name='right_wrist_yaw_link_visual'>
        <pose>0 0 0 0 0 0</pose>
        <geometry>
          <mesh>
            <scale>1 1 1</scale>
            <uri>meshes/wrist_yaw_link.STL</uri>
          </mesh>
        </geometry>
        <material>
          <diffuse>0.125 0.125 0.125 1</diffuse>
          <ambient>0.125 0.125 0.125 1</ambient>
        </material>
      </visual>
      <visual name='right_wrist_yaw_link_fixed_joint_lump__R_hand_base_link_visual_1'>
        <pose>0.053999999999999999 0 0 3.1415926535897931 0 -1.5707963267948959</pose>
        <geometry>
          <mesh>
            <scale>1 1 1</scale>
            <uri>meshes/R_hand_base_link.STL</uri>
          </mesh>
        </geometry>
        <material>
          <diffuse>0.125 0.125 0.125 1</diffuse>
          <ambient>0.125 0.125 0.125 1</ambient>
        </material>
      </visual>
    </link>
    <joint name='R_index_proximal_joint' type='revolute'>
      <pose relative_to='right_wrist_yaw_link'>0.19053 -0.0002853299999999726 0.032267999999999977 0.034892653589793099 0 -1.570796326794897</pose>
      <parent>right_wrist_yaw_link</parent>
      <child>R_index_proximal</child>
      <axis>
        <xyz>0 0 1</xyz>
        <limit>
          <lower>0</lower>
          <upper>1.7</upper>
          <effort>1</effort>
          <velocity>0.5</velocity>
        </limit>
        <dynamics>
          <spring_reference>0</spring_reference>
          <spring_stiffness>0</spring_stiffness>
        </dynamics>
      </axis>
    </joint>
    <link name='R_index_proximal'>
      <pose relative_to='R_index_proximal_joint'>0 0 0 0 0 0</pose>
      <inertial>
        <pose>0.0012259 0.011941999999999999 -0.0060001000000000004 0 0 0</pose>
        <mass>0.0042402999999999998</mass>
        <inertia>
          <ixx>6.6232000000000002e-07</ixx>
          <ixy>-1.5775000000000001e-08</ixy>
          <ixz>1.8514999999999999e-12</ixz>
          <iyy>2.1145999999999999e-07</iyy>
          <iyz>-5.0828000000000001e-12</iyz>
          <izz>6.9398000000000002e-07</izz>
        </inertia>
      </inertial>
      <collision name='R_index_proximal_collision'>
        <pose>0 0 0 0 0 0</pose>
        <geometry>
          <mesh>
            <scale>1 1 1</scale>
            <uri>meshes/link15_R.STL</uri>
          </mesh>
        </geometry>
      </collision>
      <visual name='R_index_proximal_visual'>
        <pose>0 0 0 0 0 0</pose>
        <geometry>
          <mesh>
            <scale>1 1 1</scale>
            <uri>meshes/link15_R.STL</uri>
          </mesh>
        </geometry>
        <material>
          <diffuse>0.125 0.125 0.125 1</diffuse>
          <ambient>0.125 0.125 0.125 1</ambient>
        </material>
      </visual>
    </link>
    <joint name='R_index_intermediate_joint' type='revolute'>
      <pose relative_to='R_index_proximal'>-0.0026137999999999999 0.032025999999999999 -0.001 0 0 0</pose>
      <parent>R_index_proximal</parent>
      <child>R_index_intermediate</child>
      <axis>
        <xyz>0 0 1</xyz>
        <mimic joint='R_index_proximal_joint'>
          <multiplier>1</multiplier>
          <offset>0</offset>
          <reference>0</reference>
        </mimic>
        <limit>
          <lower>0</lower>
          <upper>1.7</upper>
          <effort>1</effort>
          <velocity>0.5</velocity>
        </limit>
        <dynamics>
          <spring_reference>0</spring_reference>
          <spring_stiffness>0</spring_stiffness>
        </dynamics>
      </axis>
    </joint>
    <link name='R_index_intermediate'>
      <pose relative_to='R_index_intermediate_joint'>0 0 0 0 0 0</pose>
      <inertial>
        <pose>0.0019697 0.019588999999999999 -0.0050000000000000001 0 0 0</pose>
        <mass>0.0045683</mass>
        <inertia>
          <ixx>7.6110999999999996e-07</ixx>
          <ixy>8.7637000000000006e-08</ixy>
          <ixz>-3.7751000000000002e-13</ixz>
          <iyy>9.6076000000000006e-08</iyy>
          <iyz>9.9443999999999995e-13</iyz>
          <izz>7.8179000000000001e-07</izz>
        </inertia>
      </inertial>
      <collision name='R_index_intermediate_collision'>
        <pose>0 0 0 0 0 0</pose>
        <geometry>
          <mesh>
            <scale>1 1 1</scale>
            <uri>meshes/link16_R.STL</uri>
          </mesh>
        </geometry>
      </collision>
      <visual name='R_index_intermediate_visual'>
        <pose>0 0 0 0 0 0</pose>
        <geometry>
          <mesh>
            <scale>1 1 1</scale>
            <uri>meshes/link16_R.STL</uri>
          </mesh>
        </geometry>
        <material>
          <diffuse>0.125 0.125 0.125 1</diffuse>
          <ambient>0.125 0.125 0.125 1</ambient>
        </material>
      </visual>
    </link>
    <joint name='R_middle_proximal_joint' type='revolute'>
      <pose relative_to='right_wrist_yaw_link'>0.19109999999999999 -0.0002853299999999726 0.012949999999999981 -7.3464102068321324e-06 8.4703294725430034e-22 -1.5707963267948959</pose>
      <parent>right_wrist_yaw_link</parent>
      <child>R_middle_proximal</child>
      <axis>
        <xyz>0 0 1</xyz>
        <limit>
          <lower>0</lower>
          <upper>1.7</upper>
          <effort>1</effort>
          <velocity>0.5</velocity>
        </limit>
        <dynamics>
          <spring_reference>0</spring_reference>
          <spring_stiffness>0</spring_stiffness>
        </dynamics>
      </axis>
    </joint>
    <link name='R_middle_proximal'>
      <pose relative_to='R_middle_proximal_joint'>0 0 0 0 0 0</pose>
      <inertial>
        <pose>0.001297 0.011934 -0.0060001000000000004 0 0 0</pose>
        <mass>0.0042402999999999998</mass>
        <inertia>
          <ixx>6.6211000000000004e-07</ixx>
          <ixy>-1.8460999999999999e-08</ixy>
          <ixz>1.8001999999999999e-12</ixz>
          <iyy>2.1166999999999999e-07</iyy>
          <iyz>-6.6808000000000004e-12</iyz>
          <izz>6.9396999999999996e-07</izz>
        </inertia>
      </inertial>
      <collision name='R_middle_proximal_collision'>
        <pose>0 0 0 0 0 0</pose>
        <geometry>
          <mesh>
            <scale>1 1 1</scale>
            <uri>meshes/link17_R.STL</uri>
          </mesh>
        </geometry>
      </collision>
      <visual name='R_middle_proximal_visual'>
        <pose>0 0 0 0 0 0</pose>
        <geometry>
          <mesh>
            <scale>1 1 1</scale>
            <uri>meshes/link17_R.STL</uri>
          </mesh>
        </geometry>
        <material>
          <diffuse>0.125 0.125 0.125 1</diffuse>
          <ambient>0.125 0.125 0.125 1</ambient>
        </material>
      </visual>
    </link>
    <joint name='R_middle_intermediate_joint' type='revolute'>
      <pose relative_to='R_middle_proximal'>-0.0024229 0.032041 -0.001 0 0 0</pose>
      <parent>R_middle_proximal</parent>
      <child>R_middle_intermediate</child>
      <axis>
        <xyz>0 0 1</xyz>
        <mimic joint='R_middle_proximal_joint'>
          <multiplier>1</multiplier>
          <offset>0</offset>
          <reference>0</reference>
        </mimic>
        <limit>
          <lower>0</lower>
          <upper>1.7</upper>
          <effort>1</effort>
          <velocity>0.5</velocity>
        </limit>
        <dynamics>
          <spring_reference>0</spring_reference>
          <spring_stiffness>0</spring_stiffness>
        </dynamics>
      </axis>
    </joint>
    <link name='R_middle_intermediate'>
      <pose relative_to='R_middle_intermediate_joint'>0 0 0 0 0 0</pose>
      <inertial>
        <pose>0.001921 0.020795999999999999 -0.0050000000000000001 0 0 0</pose>
        <mass>0.0050396</mass>
        <inertia>
          <ixx>9.5821999999999991e-07</ixx>
          <ixy>1.1424999999999999e-07</ixy>
          <ixz>-2.4790999999999998e-12</ixz>
          <iyy>1.0646e-07</iyy>
          <iyz>5.9173000000000002e-12</iyz>
          <izz>9.8384000000000005e-07</izz>
        </inertia>
      </inertial>
      <collision name='R_middle_intermediate_collision'>
        <pose>0 0 0 0 0 0</pose>
        <geometry>
          <mesh>
            <scale>1 1 1</scale>
            <uri>meshes/link18_R.STL</uri>
          </mesh>
        </geometry>
      </collision>
      <visual name='R_middle_intermediate_visual'>
        <pose>0 0 0 0 0 0</pose>
        <geometry>
          <mesh>
            <scale>1 1 1</scale>
            <uri>meshes/link18_R.STL</uri>
          </mesh>
        </geometry>
        <material>
          <diffuse>0.125 0.125 0.125 1</diffuse>
          <ambient>0.125 0.125 0.125 1</ambient>
        </material>
      </visual>
    </link>
    <joint name='R_pinky_proximal_joint' type='revolute'>
      <pose relative_to='right_wrist_yaw_link'>0.18970999999999999 -0.0002853299999999726 -0.025488000000000011 -0.1046926535897932 -6.9388939039072284e-18 -1.5707963267948972</pose>
      <parent>right_wrist_yaw_link</parent>
      <child>R_pinky_proximal</child>
      <axis>
        <xyz>0 0 1</xyz>
        <limit>
          <lower>0</lower>
          <upper>1.7</upper>
          <effort>1</effort>
          <velocity>0.5</velocity>
        </limit>
        <dynamics>
          <spring_reference>0</spring_reference>
          <spring_stiffness>0</spring_stiffness>
        </dynamics>
      </axis>
    </joint>
    <link name='R_pinky_proximal'>
      <pose relative_to='R_pinky_proximal_joint'>0 0 0 0 0 0</pose>
      <inertial>
        <pose>0.001297 0.011934 -0.0060001000000000004 0 0 0</pose>
        <mass>0.0042402999999999998</mass>
        <inertia>
          <ixx>6.6211000000000004e-07</ixx>
          <ixy>-1.8460999999999999e-08</ixy>
          <ixz>1.6907000000000001e-12</ixz>
          <iyy>2.1166999999999999e-07</iyy>
          <iyz>-6.9334000000000003e-12</iyz>
          <izz>6.9396999999999996e-07</izz>
        </inertia>
      </inertial>
      <collision name='R_pinky_proximal_collision'>
        <pose>0 0 0 0 0 0</pose>
        <geometry>
          <mesh>
            <scale>1 1 1</scale>
            <uri>meshes/link21_R.STL</uri>
          </mesh>
        </geometry>
      </collision>
      <visual name='R_pinky_proximal_visual'>
        <pose>0 0 0 0 0 0</pose>
        <geometry>
          <mesh>
            <scale>1 1 1</scale>
            <uri>meshes/link21_R.STL</uri>
          </mesh>
        </geometry>
        <material>
          <diffuse>0.125 0.125 0.125 1</diffuse>
          <ambient>0.125 0.125 0.125 1</ambient>
        </material>
      </visual>
    </link>
    <joint name='R_pinky_intermediate_joint' type='revolute'>
      <pose relative_to='R_pinky_proximal'>-0.0024229 0.032041 -0.001 0 0 0</pose>
      <parent>R_pinky_proximal</parent>
      <child>R_pinky_intermediate</child>
      <axis>
        <xyz>0 0 1</xyz>
        <mimic joint='R_pinky_proximal_joint'>
          <multiplier>1</multiplier>
          <offset>0</offset>
          <reference>0</reference>
        </mimic>
        <limit>
          <lower>0</lower>
          <upper>1.7</upper>
          <effort>1</effort>
          <velocity>0.5</velocity>
        </limit>
        <dynamics>
          <spring_reference>0</spring_reference>
          <spring_stiffness>0</spring_stiffness>
        </dynamics>
      </axis>
    </joint>
    <link name='R_pinky_intermediate'>
      <pose relative_to='R_pinky_intermediate_joint'>0 0 0 0 0 0</pose>
      <inertial>
        <pose>0.0024748000000000001 0.016202999999999999 -0.0050030999999999999 0 0 0</pose>
        <mass>0.0035996000000000001</mass>
        <inertia>
          <ixx>4.3912999999999999e-07</ixx>
          <ixy>4.1418000000000001e-08</ixy>
          <ixz>3.7168000000000002e-11</ixz>
          <iyy>7.0246999999999994e-08</iyy>
          <iyz>5.8613000000000005e-11</iyz>
          <izz>4.4867000000000001e-07</izz>
        </inertia>
      </inertial>
      <collision name='R_pinky_intermediate_collision'>
        <pose>0 0 0 0 0 0</pose>
        <geometry>
          <mesh>
            <scale>1 1 1</scale>
            <uri>meshes/link22_R.STL</uri>
          </mesh>
        </geometry>
      </collision>
      <visual name='R_pinky_intermediate_visual'>
        <pose>0 0 0 0 0 0</pose>
        <geometry>
          <mesh>
            <scale>1 1 1</scale>
            <uri>meshes/link22_R.STL</uri>
          </mesh>
        </geometry>
        <material>
          <diffuse>0.125 0.125 0.125 1</diffuse>
          <ambient>0.125 0.125 0.125 1</ambient>
        </material>
      </visual>
    </link>
    <joint name='R_ring_proximal_joint' type='revolute'>
      <pose relative_to='right_wrist_yaw_link'>0.19091 -0.0002853299999999726 -0.0062872000000000153 -0.05239265358979342 -3.4694469519536142e-18 -1.570796326794897</pose>
      <parent>right_wrist_yaw_link</parent>
      <child>R_ring_proximal</child>
      <axis>
        <xyz>0 0 1</xyz>
        <limit>
          <lower>0</lower>
          <upper>1.7</upper>
          <effort>1</effort>
          <velocity>0.5</velocity>
        </limit>
        <dynamics>
          <spring_reference>0</spring_reference>
          <spring_stiffness>0</spring_stiffness>
        </dynamics>
      </axis>
    </joint>
    <link name='R_ring_proximal'>
      <pose relative_to='R_ring_proximal_joint'>0 0 0 0 0 0</pose>
      <inertial>
        <pose>0.001297 0.011934 -0.0060001999999999998 0 0 0</pose>
        <mass>0.0042402999999999998</mass>
        <inertia>
          <ixx>6.6211000000000004e-07</ixx>
          <ixy>-1.8460999999999999e-08</ixy>
          <ixz>1.5792999999999999e-12</ixz>
          <iyy>2.1166999999999999e-07</iyy>
          <iyz>-6.6868000000000001e-12</iyz>
          <izz>6.9396999999999996e-07</izz>
        </inertia>
      </inertial>
      <collision name='R_ring_proximal_collision'>
        <pose>0 0 0 0 0 0</pose>
        <geometry>
          <mesh>
            <scale>1 1 1</scale>
            <uri>meshes/link19_R.STL</uri>
          </mesh>
        </geometry>
      </collision>
      <visual name='R_ring_proximal_visual'>
        <pose>0 0 0 0 0 0</pose>
        <geometry>
          <mesh>
            <scale>1 1 1</scale>
            <uri>meshes/link19_R.STL</uri>
          </mesh>
        </geometry>
        <material>
          <diffuse>0.125 0.125 0.125 1</diffuse>
          <ambient>0.125 0.125 0.125 1</ambient>
        </material>
      </visual>
    </link>
    <joint name='R_ring_intermediate_joint' type='revolute'>
      <pose relative_to='R_ring_proximal'>-0.0024229 0.032041 -0.001 0 0 0</pose>
      <parent>R_ring_proximal</parent>
      <child>R_ring_intermediate</child>
      <axis>
        <xyz>0 0 1</xyz>
        <mimic joint='R_ring_proximal_joint'>
          <multiplier>1</multiplier>
          <offset>0</offset>
          <reference>0</reference>
        </mimic>
        <limit>
          <lower>0</lower>
          <upper>1.7</upper>
          <effort>1</effort>
          <velocity>0.5</velocity>
        </limit>
        <dynamics>
          <spring_reference>0</spring_reference>
          <spring_stiffness>0</spring_stiffness>
        </dynamics>
      </axis>
    </joint>
    <link name='R_ring_intermediate'>
      <pose relative_to='R_ring_intermediate_joint'>0 0 0 0 0 0</pose>
      <inertial>
        <pose>0.0021752999999999998 0.019567000000000001 -0.0050000000000000001 0 0 0</pose>
        <mass>0.0045683</mass>
        <inertia>
          <ixx>7.6285999999999999e-07</ixx>
          <ixy>8.0634999999999994e-08</ixy>
          <ixz>-6.1561999999999996e-13</ixz>
          <iyy>9.4310000000000002e-08</iyy>
          <iyz>5.8619000000000005e-13</iyz>
          <izz>7.8176999999999999e-07</izz>
        </inertia>
      </inertial>
      <collision name='R_ring_intermediate_collision'>
        <pose>0 0 0 0 0 0</pose>
        <geometry>
          <mesh>
            <scale>1 1 1</scale>
            <uri>meshes/link20_R.STL</uri>
          </mesh>
        </geometry>
      </collision>
      <visual name='R_ring_intermediate_visual'>
        <pose>0 0 0 0 0 0</pose>
        <geometry>
          <mesh>
            <scale>1 1 1</scale>
            <uri>meshes/link20_R.STL</uri>
          </mesh>
        </geometry>
        <material>
          <diffuse>0.125 0.125 0.125 1</diffuse>
          <ambient>0.125 0.125 0.125 1</ambient>
        </material>
      </visual>
    </link>
    <joint name='R_thumb_proximal_yaw_joint' type='revolute'>
      <pose relative_to='right_wrist_yaw_link'>0.1231 0.01696000000000002 0.020449999999999989 1.5707999999538003 1.5707926535755432 1.5707963267344471</pose>
      <parent>right_wrist_yaw_link</parent>
      <child>R_thumb_proximal_base</child>
      <axis>
        <xyz>0 0 -1</xyz>
        <limit>
          <lower>-0.10000000000000001</lower>
          <upper>1.3</upper>
          <effort>1</effort>
          <velocity>0.5</velocity>
        </limit>
        <dynamics>
          <spring_reference>0</spring_reference>
          <spring_stiffness>0</spring_stiffness>
        </dynamics>
      </axis>
    </joint>
    <link name='R_thumb_proximal_base'>
      <pose relative_to='R_thumb_proximal_yaw_joint'>0 0 0 0 0 0</pose>
      <inertial>
        <pose>-0.0048063999999999997 0.00093820000000000004 -0.0075700000000000003 0 0 0</pose>
        <mass>0.0018868999999999999</mass>
        <inertia>
          <ixx>5.8159999999999999e-08</ixx>
          <ixy>1.4539e-08</ixy>
          <ixz>4.4910000000000003e-09</ixz>
          <iyy>7.9161000000000003e-08</iyy>
          <iyz>-1.8727e-09</iyz>
          <izz>6.7433000000000006e-08</izz>
        </inertia>
      </inertial>
      <collision name='R_thumb_proximal_base_collision'>
        <pose>0 0 0 0 0 0</pose>
        <geometry>
          <mesh>
            <scale>1 1 1</scale>
            <uri>meshes/link11_R.STL</uri>
          </mesh>
        </geometry>
      </collision>
      <visual name='R_thumb_proximal_base_visual'>
        <pose>0 0 0 0 0 0</pose>
        <geometry>
          <mesh>
            <scale>1 1 1</scale>
            <uri>meshes/link11_R.STL</uri>
          </mesh>
        </geometry>
        <material>
          <diffuse>0.125 0.125 0.125 1</diffuse>
          <ambient>0.125 0.125 0.125 1</ambient>
        </material>
      </visual>
    </link>
    <joint name='R_thumb_proximal_pitch_joint' type='revolute'>
      <pose relative_to='R_thumb_proximal_base'>-0.0088099000000000007 0.010892000000000001 -0.0092499999999999995 1.5708 0 2.8586999999999998</pose>
      <parent>R_thumb_proximal_base</parent>
      <child>R_thumb_proximal</child>
      <axis>
        <xyz>0 0 1</xyz>
        <limit>
          <lower>-0.10000000000000001</lower>
          <upper>0.59999999999999998</upper>
          <effort>1</effort>
          <velocity>0.5</velocity>
        </limit>
        <dynamics>
          <spring_reference>0</spring_reference>
          <spring_stiffness>0</spring_stiffness>
        </dynamics>
      </axis>
    </joint>
    <link name='R_thumb_proximal'>
      <pose relative_to='R_thumb_proximal_pitch_joint'>0 0 0 0 0 0</pose>
      <inertial>
        <pose>0.021932 0.012784999999999999 -0.0080385999999999999 0 0 0</pose>
        <mass>0.0066074999999999997</mass>
        <inertia>
          <ixx>1.5685999999999999e-06</ixx>
          <ixy>-7.8296000000000002e-07</ixy>
          <ixz>8.9142999999999999e-10</ixz>
          <iyy>1.7352999999999999e-06</iyy>
          <iyz>-1.0190999999999999e-09</iyz>
          <izz>2.7860000000000001e-06</izz>
        </inertia>
      </inertial>
      <collision name='R_thumb_proximal_collision'>
        <pose>0 0 0 0 0 0</pose>
        <geometry>
          <mesh>
            <scale>1 1 1</scale>
            <uri>meshes/link12_R.STL</uri>
          </mesh>
        </geometry>
      </collision>
      <visual name='R_thumb_proximal_visual'>
        <pose>0 0 0 0 0 0</pose>
        <geometry>
          <mesh>
            <scale>1 1 1</scale>
            <uri>meshes/link12_R.STL</uri>
          </mesh>
        </geometry>
        <material>
          <diffuse>0.125 0.125 0.125 1</diffuse>
          <ambient>0.125 0.125 0.125 1</ambient>
        </material>
      </visual>
    </link>
    <joint name='R_thumb_intermediate_joint' type='revolute'>
      <pose relative_to='R_thumb_proximal'>0.044069999999999998 0.034553 -0.00080000000000000004 0 0 0</pose>
      <parent>R_thumb_proximal</parent>
      <child>R_thumb_intermediate</child>
      <axis>
        <xyz>0 0 1</xyz>
        <mimic joint='R_thumb_proximal_pitch_joint'>
          <multiplier>1.6000000000000001</multiplier>
          <offset>0</offset>
          <reference>0</reference>
        </mimic>
        <limit>
          <lower>0</lower>
          <upper>0.80000000000000004</upper>
          <effort>1</effort>
          <velocity>0.5</velocity>
        </limit>
        <dynamics>
          <spring_reference>0</spring_reference>
          <spring_stiffness>0</spring_stiffness>
        </dynamics>
      </axis>
    </joint>
    <link name='R_thumb_intermediate'>
      <pose relative_to='R_thumb_intermediate_joint'>0 0 0 0 0 0</pose>
      <inertial>
        <pose>0.0095543999999999994 -0.0016282 -0.0071996999999999998 0 0 0</pose>
        <mass>0.0037847000000000002</mass>
        <inertia>
          <ixx>3.6981e-07</ixx>
          <ixy>-9.8581000000000001e-08</ixy>
          <ixz>-4.7469000000000003e-12</ixz>
          <iyy>3.2393999999999997e-07</iyy>
          <iyz>1.0939e-12</iyz>
          <izz>4.6530999999999998e-07</izz>
        </inertia>
      </inertial>
      <collision name='R_thumb_intermediate_collision'>
        <pose>0 0 0 0 0 0</pose>
        <geometry>
          <mesh>
            <scale>1 1 1</scale>
            <uri>meshes/link13_R.STL</uri>
          </mesh>
        </geometry>
      </collision>
      <visual name='R_thumb_intermediate_visual'>
        <pose>0 0 0 0 0 0</pose>
        <geometry>
          <mesh>
            <scale>1 1 1</scale>
            <uri>meshes/link13_R.STL</uri>
          </mesh>
        </geometry>
        <material>
          <diffuse>0.125 0.125 0.125 1</diffuse>
          <ambient>0.125 0.125 0.125 1</ambient>
        </material>
      </visual>
    </link>
    <joint name='R_thumb_distal_joint' type='revolute'>
      <pose relative_to='R_thumb_intermediate'>0.020247999999999999 0.010156 -0.0011999999999999999 0 0 0</pose>
      <parent>R_thumb_intermediate</parent>
      <child>R_thumb_distal</child>
      <axis>
        <xyz>0 0 1</xyz>
        <mimic joint='R_thumb_proximal_pitch_joint'>
          <multiplier>2.3999999999999999</multiplier>
          <offset>0</offset>
          <reference>0</reference>
        </mimic>
        <limit>
          <lower>0</lower>
          <upper>1.2</upper>
          <effort>1</effort>
          <velocity>0.5</velocity>
        </limit>
        <dynamics>
          <spring_reference>0</spring_reference>
          <spring_stiffness>0</spring_stiffness>
        </dynamics>
      </axis>
    </joint>
    <link name='R_thumb_distal'>
      <pose relative_to='R_thumb_distal_joint'>0 0 0 0 0 0</pose>
      <inertial>
        <pose>0.0092887999999999998 0.0049528999999999997 -0.0060032999999999996 0 0 0</pose>
        <mass>0.0033441</mass>
        <inertia>
          <ixx>1.3631999999999999e-07</ixx>
          <ixy>-5.6787999999999999e-08</ixy>
          <ixz>-9.2763999999999994e-11</ixz>
          <iyy>1.4051999999999999e-07</iyy>
          <iyz>-1.2283e-10</iyz>
          <izz>2.0025999999999999e-07</izz>
        </inertia>
      </inertial>
      <collision name='R_thumb_distal_collision'>
        <pose>0 0 0 0 0 0</pose>
        <geometry>
          <mesh>
            <scale>1 1 1</scale>
            <uri>meshes/link14_R.STL</uri>
          </mesh>
        </geometry>
      </collision>
      <visual name='R_thumb_distal_visual'>
        <pose>0 0 0 0 0 0</pose>
        <geometry>
          <mesh>
            <scale>1 1 1</scale>
            <uri>meshes/link14_R.STL</uri>
          </mesh>
        </geometry>
        <material>
          <diffuse>0.125 0.125 0.125 1</diffuse>
          <ambient>0.125 0.125 0.125 1</ambient>
        </material>
      </visual>
    </link>
    <frame name='camera_joint' attached_to='torso_link'>
      <pose>0.11108999999999999 0.017500000000000002 0.68789 0 0.88592912831232185 0</pose>
    </frame>
    <frame name='camera_link' attached_to='camera_joint'>
      <pose>0 0 0 0 0 0</pose>
    </frame>
    <frame name='imu_joint' attached_to='torso_link'>
      <pose>-0.044519999999999997 -0.01891 0.27755999999999997 0 0 0</pose>
    </frame>
    <frame name='imu_link' attached_to='imu_joint'>
      <pose>0 0 0 0 0 0</pose>
    </frame>
    <frame name='lidar_joint' attached_to='torso_link'>
      <pose>0.048739999999999999 0 0.67979999999999996 0 0.24015730507442004 0</pose>
    </frame>
    <frame name='lidar_link' attached_to='lidar_joint'>
      <pose>0 0 0 0 0 0</pose>
    </frame>
    <frame name='logo_joint' attached_to='torso_link'>
      <pose>0 0 0 0 0 0</pose>
    </frame>
    <frame name='logo_link' attached_to='logo_joint'>
      <pose>0 0 0 0 0 0</pose>
    </frame>
    <frame name='L_base_link_joint' attached_to='left_wrist_yaw_link'>
      <pose>0.053999999999999999 0 0 0 0 1.5707963267948959</pose>
    </frame>
    <frame name='L_hand_base_link' attached_to='L_base_link_joint'>
      <pose>0 0 0 0 0 0</pose>
    </frame>
    <frame name='R_base_link_joint' attached_to='right_wrist_yaw_link'>
      <pose>0.053999999999999999 0 0 3.1415926535897931 0 -1.5707963267948959</pose>
    </frame>
    <frame name='R_hand_base_link' attached_to='R_base_link_joint'>
      <pose>0 0 0 0 0 0</pose>
    </frame>
  </model>
</sdf>
